Workbook

Sheet Export Summary
B3: This document was exported from Numbers. Each table was converted to an Excel worksheet. All other objects on each Numbers sheet were placed on separate worksheets. Please be aware that formula calculations may differ in Excel.
B7: Numbers Sheet Name | C7: Numbers Table Name | D7: Excel Worksheet Name
B9: סיכום
C10: Table 1 | D10: סיכום
B11: ניתוח חודשי
C12: Table 1 | D12: ניתוח חודשי
B13: ניתוח קטגוריות
C14: Table 1 | D14: ניתוח קטגוריות
B15: המלצות
C16: Table 1 | D16: המלצות
B17: בתי עסק
C18: Table 1 | D18: בתי עסק
B19: עסקאות
C20: Table 1 | D20: עסקאות
B21: הכנסות
C22: Table 1 | D22: הכנסות
B23: פירוט חופשות
C24: Table 1 | D24: פירוט חופשות
B25: מיפוי ומקורות
C26: Table 1 | D26: מיפוי ומקורות

Sheet סיכום
B2: ניתוח הוצאות משק בית
B3: 2 נפשות | ינואר 2025 עד אוגוסט 2026 | סכומים בש״ח
B6: מדד | C6: ערך
B7: חודשים בניתוח | C7: 20
B8: שורות עסקאות | C8: 1957
B9: הוצאות מקור נטו | C9: 733923
B10: הוצאות תקניות | C10: 819305
B11: הוצאה שוטפת חודשית | C11: 22579.05
B12: הוצאה שוטפת לנפש | C12: 11289.525
B13: הכנסה תקנית | C13: 1725864
B14: חיסכון מצטבר | C14: 906559
B17: השוואת הוצאה שוטפת | C17: 2025 | D17: 2026 (8 ח׳)
B18: ממוצע חודשי | C18: 22559 | D18: 22609.125
B19: ממוצע לנפש | C19: 11279.5 | D19: 11304.562
B20: שינוי לעומת 2025 | D20: 0.0022219513
F22: תקופה | G22: הוצאות תקניות | H22: הוצאות שוטפות | J22: מס׳ | K22: ממצא | L22: פירוט
F23: 2025-01 | G23: 43507 | H23: 23605 | J23: 1 | K23: ההוצאה השוטפת יציבה | L23: ₪22,559 לחודש ב־2025 לעומת ₪22,609 ב־2026 — שינוי של 0.2%.
F24: 2025-02 | G24: 55680 | H24: 23441 | J24: 2 | K24: הדיור הוא השינוי המבני המרכזי | L24: שכר הדירה עלה מכ־₪6,458 לחודש ב־2025 ל־₪8,000 ב־2026. יתר הסעיפים הגמישים ירדו בחלקם וקיזזו את העלייה.
F25: 2025-03 | G25: 56799 | H25: 28602 | J25: 3 | K25: אוכל נשאר יציב יחסית | L25: מזון לבית ואוכל בחוץ יחד הם כ־₪3,600 לחודש למשק הבית, כ־₪1,800 לאדם.
F26: 2025-04 | G26: 38753 | H26: 24197 | J26: 4 | K26: הוצאות בריאות וספורט מהותיות | L26: אין המלצה לקצץ טיפול; יש לבדוק החזרים וכפל כיסוי. בספורט יש מקום לבדוק חפיפה בין מסגרות.
F27: 2025-05 | G27: 78552 | H27: 16883 | J27: 5 | K27: פוטנציאל החיסכון השמרני | L27: תרחיש ללא שינוי חד באורח החיים מכוון לכ־₪600–₪1,200 בחודש, בעיקר דרך תקציב גמיש, אוכל, ספקים וחפיפות.
F28: 2025-06 | G28: 31005 | H28: 23150
F29: 2025-07 | G29: 36910 | H29: 13450
F30: 2025-08 | G30: 33987 | H30: 21360
F31: 2025-09 | G31: 33640 | H31: 26039
F32: 2025-10 | G32: 44496 | H32: 18846
F33: 2025-11 | G33: 32456 | H33: 22159
F34: 2025-12 | G34: 47902 | H34: 28976
F35: 2026-01 | G35: 27251 | H35: 21001
F36: 2026-02 | G36: 26956 | H36: 20873
F37: 2026-03 | G37: 30147 | H37: 23144
F38: 2026-04 | G38: 32684 | H38: 24902
F39: 2026-05 | G39: 33320 | H39: 22338
... F42: 2026-08 | G42: 34550 | H42: 26839

Sheet ניתוח חודשי
B2: ניתוח חודשי
B3: הוצאות והכנסות מנורמלות; אוגוסט 2026 מסומן כחודש פתוח
B6: חודש | C6: תקופה | D6: סטטוס | E6: הוצאות תקניות (₪) | F6: הוצאות שוטפות (₪) | G6: שוטף לנפש (₪) | H6: הכנסה רשומה (₪) | I6: הכנסה שסווגה מחדש (₪) | J6: הכנסה תקנית (₪) | K6: חיסכון (₪) | L6: שיעור חיסכון | M6: ממוצע שוטף 3 ח׳ (₪)
B7: 45658 | C7: 2025-01 | D7: סגור | E7: {=_xlfn.SUMIFS('עסקאות'!$M$2:$M$1958,'עסקאות'!$A$2:$A$1958,B7)} -> 43507 | F7: {=_xlfn.SUMIFS('עסקאות'!$N$2:$N$1958,'עסקאות'!$A$2:$A$1958,B7)} -> 23605 | G7: {=F7/2} -> 11802.5 | H7: {=_xlfn.SUMIFS('הכנסות'!$D$2:$D$98,'הכנסות'!$A$2:$A$98,B7)} -> 146408 | I7: {=_xlfn.SUMIFS('עסקאות'!$O$2:$O$1958,'עסקאות'!$A$2:$A$1958,B7)} -> 6643 | J7: {=H7+I7} -> 153051 | K7: {=J7-E7} -> 109544 | L7: {=IF(J7=0,"",K7/J7)} -> 0.71573528
B8: 45689 | C8: 2025-02 | D8: סגור | E8: {=_xlfn.SUMIFS('עסקאות'!$M$2:$M$1958,'עסקאות'!$A$2:$A$1958,B8)} -> 55680 | F8: {=_xlfn.SUMIFS('עסקאות'!$N$2:$N$1958,'עסקאות'!$A$2:$A$1958,B8)} -> 23441 | G8: {=F8/2} -> 11720.5 | H8: {=_xlfn.SUMIFS('הכנסות'!$D$2:$D$98,'הכנסות'!$A$2:$A$98,B8)} -> 39979 | I8: {=_xlfn.SUMIFS('עסקאות'!$O$2:$O$1958,'עסקאות'!$A$2:$A$1958,B8)} -> 6663 | J8: {=H8+I8} -> 46642 | K8: {=J8-E8} -> -9038 | L8: {=IF(J8=0,"",K8/J8)} -> -0.19377385
B9: 45717 | C9: 2025-03 | D9: סגור | E9: {=_xlfn.SUMIFS('עסקאות'!$M$2:$M$1958,'עסקאות'!$A$2:$A$1958,B9)} -> 56799 | F9: {=_xlfn.SUMIFS('עסקאות'!$N$2:$N$1958,'עסקאות'!$A$2:$A$1958,B9)} -> 28602 | G9: {=F9/2} -> 14301 | H9: {=_xlfn.SUMIFS('הכנסות'!$D$2:$D$98,'הכנסות'!$A$2:$A$98,B9)} -> 70123 | I9: {=_xlfn.SUMIFS('עסקאות'!$O$2:$O$1958,'עסקאות'!$A$2:$A$1958,B9)} -> 6989 | J9: {=H9+I9} -> 77112 | K9: {=J9-E9} -> 20313 | L9: {=IF(J9=0,"",K9/J9)} -> 0.26342204 | M9: {=AVERAGE(F7:F9)} -> 25216
B10: 45748 | C10: 2025-04 | D10: סגור | E10: {=_xlfn.SUMIFS('עסקאות'!$M$2:$M$1958,'עסקאות'!$A$2:$A$1958,B10)} -> 38753 | F10: {=_xlfn.SUMIFS('עסקאות'!$N$2:$N$1958,'עסקאות'!$A$2:$A$1958,B10)} -> 24197 | G10: {=F10/2} -> 12098.5 | H10: {=_xlfn.SUMIFS('הכנסות'!$D$2:$D$98,'הכנסות'!$A$2:$A$98,B10)} -> 34053 | I10: {=_xlfn.SUMIFS('עסקאות'!$O$2:$O$1958,'עסקאות'!$A$2:$A$1958,B10)} -> 8137 | J10: {=H10+I10} -> 42190 | K10: {=J10-E10} -> 3437 | L10: {=IF(J10=0,"",K10/J10)} -> 0.081464802 | M10: {=AVERAGE(F8:F10)} -> 25413.333
B11: 45778 | C11: 2025-05 | D11: סגור | E11: {=_xlfn.SUMIFS('עסקאות'!$M$2:$M$1958,'עסקאות'!$A$2:$A$1958,B11)} -> 78552 | F11: {=_xlfn.SUMIFS('עסקאות'!$N$2:$N$1958,'עסקאות'!$A$2:$A$1958,B11)} -> 16883 | G11: {=F11/2} -> 8441.5 | H11: {=_xlfn.SUMIFS('הכנסות'!$D$2:$D$98,'הכנסות'!$A$2:$A$98,B11)} -> 19799 | I11: {=_xlfn.SUMIFS('עסקאות'!$O$2:$O$1958,'עסקאות'!$A$2:$A$1958,B11)} -> 6500 | J11: {=H11+I11} -> 26299 | K11: {=J11-E11} -> -52253 | L11: {=IF(J11=0,"",K11/J11)} -> -1.9868816 | M11: {=AVERAGE(F9:F11)} -> 23227.333
B12: 45809 | C12: 2025-06 | D12: סגור | E12: {=_xlfn.SUMIFS('עסקאות'!$M$2:$M$1958,'עסקאות'!$A$2:$A$1958,B12)} -> 31005 | F12: {=_xlfn.SUMIFS('עסקאות'!$N$2:$N$1958,'עסקאות'!$A$2:$A$1958,B12)} -> 23150 | G12: {=F12/2} -> 11575 | H12: {=_xlfn.SUMIFS('הכנסות'!$D$2:$D$98,'הכנסות'!$A$2:$A$98,B12)} -> 0 | I12: {=_xlfn.SUMIFS('עסקאות'!$O$2:$O$1958,'עסקאות'!$A$2:$A$1958,B12)} -> 6500 | J12: {=H12+I12} -> 6500 | K12: {=J12-E12} -> -24505 | L12: {=IF(J12=0,"",K12/J12)} -> -3.77 | M12: {=AVERAGE(F10:F12)} -> 21410
B13: 45839 | C13: 2025-07 | D13: סגור | E13: {=_xlfn.SUMIFS('עסקאות'!$M$2:$M$1958,'עסקאות'!$A$2:$A$1958,B13)} -> 36910 | F13: {=_xlfn.SUMIFS('עסקאות'!$N$2:$N$1958,'עסקאות'!$A$2:$A$1958,B13)} -> 13450 | G13: {=F13/2} -> 6725 | H13: {=_xlfn.SUMIFS('הכנסות'!$D$2:$D$98,'הכנסות'!$A$2:$A$98,B13)} -> 15296 | I13: {=_xlfn.SUMIFS('עסקאות'!$O$2:$O$1958,'עסקאות'!$A$2:$A$1958,B13)} -> 6924 | J13: {=H13+I13} -> 22220 | K13: {=J13-E13} -> -14690 | L13: {=IF(J13=0,"",K13/J13)} -> -0.66111611 | M13: {=AVERAGE(F11:F13)} -> 17827.667
B14: 45870 | C14: 2025-08 | D14: סגור | E14: {=_xlfn.SUMIFS('עסקאות'!$M$2:$M$1958,'עסקאות'!$A$2:$A$1958,B14)} -> 33987 | F14: {=_xlfn.SUMIFS('עסקאות'!$N$2:$N$1958,'עסקאות'!$A$2:$A$1958,B14)} -> 21360 | G14: {=F14/2} -> 10680 | H14: {=_xlfn.SUMIFS('הכנסות'!$D$2:$D$98,'הכנסות'!$A$2:$A$98,B14)} -> 15305 | I14: {=_xlfn.SUMIFS('עסקאות'!$O$2:$O$1958,'עסקאות'!$A$2:$A$1958,B14)} -> 6716 | J14: {=H14+I14} -> 22021 | K14: {=J14-E14} -> -11966 | L14: {=IF(J14=0,"",K14/J14)} -> -0.5433904 | M14: {=AVERAGE(F12:F14)} -> 19320
B15: 45901 | C15: 2025-09 | D15: סגור | E15: {=_xlfn.SUMIFS('עסקאות'!$M$2:$M$1958,'עסקאות'!$A$2:$A$1958,B15)} -> 33640 | F15: {=_xlfn.SUMIFS('עסקאות'!$N$2:$N$1958,'עסקאות'!$A$2:$A$1958,B15)} -> 26039 | G15: {=F15/2} -> 13019.5 | H15: {=_xlfn.SUMIFS('הכנסות'!$D$2:$D$98,'הכנסות'!$A$2:$A$98,B15)} -> 29670 | I15: {=_xlfn.SUMIFS('עסקאות'!$O$2:$O$1958,'עסקאות'!$A$2:$A$1958,B15)} -> 6500 | J15: {=H15+I15} -> 36170 | K15: {=J15-E15} -> 2530 | L15: {=IF(J15=0,"",K15/J15)} -> 0.06994747 | M15: {=AVERAGE(F13:F15)} -> 20283
B16: 45931 | C16: 2025-10 | D16: סגור | E16: {=_xlfn.SUMIFS('עסקאות'!$M$2:$M$1958,'עסקאות'!$A$2:$A$1958,B16)} -> 44496 | F16: {=_xlfn.SUMIFS('עסקאות'!$N$2:$N$1958,'עסקאות'!$A$2:$A$1958,B16)} -> 18846 | G16: {=F16/2} -> 9423 | H16: {=_xlfn.SUMIFS('הכנסות'!$D$2:$D$98,'הכנסות'!$A$2:$A$98,B16)} -> 79627 | I16: {=_xlfn.SUMIFS('עסקאות'!$O$2:$O$1958,'עסקאות'!$A$2:$A$1958,B16)} -> 5563 | J16: {=H16+I16} -> 85190 | K16: {=J16-E16} -> 40694 | L16: {=IF(J16=0,"",K16/J16)} -> 0.47768517 | M16: {=AVERAGE(F14:F16)} -> 22081.667
B17: 45962 | C17: 2025-11 | D17: סגור | E17: {=_xlfn.SUMIFS('עסקאות'!$M$2:$M$1958,'עסקאות'!$A$2:$A$1958,B17)} -> 32456 | F17: {=_xlfn.SUMIFS('עסקאות'!$N$2:$N$1958,'עסקאות'!$A$2:$A$1958,B17)} -> 22159 | G17: {=F17/2} -> 11079.5 | H17: {=_xlfn.SUMIFS('הכנסות'!$D$2:$D$98,'הכנסות'!$A$2:$A$98,B17)} -> 447442 | I17: {=_xlfn.SUMIFS('עסקאות'!$O$2:$O$1958,'עסקאות'!$A$2:$A$1958,B17)} -> 11701 | J17: {=H17+I17} -> 459143 | K17: {=J17-E17} -> 426687 | L17: {=IF(J17=0,"",K17/J17)} -> 0.92931178 | M17: {=AVERAGE(F15:F17)} -> 22348
B18: 45992 | C18: 2025-12 | D18: סגור | E18: {=_xlfn.SUMIFS('עסקאות'!$M$2:$M$1958,'עסקאות'!$A$2:$A$1958,B18)} -> 47902 | F18: {=_xlfn.SUMIFS('עסקאות'!$N$2:$N$1958,'עסקאות'!$A$2:$A$1958,B18)} -> 28976 | G18: {=F18/2} -> 14488 | H18: {=_xlfn.SUMIFS('הכנסות'!$D$2:$D$98,'הכנסות'!$A$2:$A$98,B18)} -> 107604 | I18: {=_xlfn.SUMIFS('עסקאות'!$O$2:$O$1958,'עסקאות'!$A$2:$A$1958,B18)} -> 6546 | J18: {=H18+I18} -> 114150 | K18: {=J18-E18} -> 66248 | L18: {=IF(J18=0,"",K18/J18)} -> 0.58035918 | M18: {=AVERAGE(F16:F18)} -> 23327
B19: 46023 | C19: 2026-01 | D19: סגור | E19: {=_xlfn.SUMIFS('עסקאות'!$M$2:$M$1958,'עסקאות'!$A$2:$A$1958,B19)} -> 27251 | F19: {=_xlfn.SUMIFS('עסקאות'!$N$2:$N$1958,'עסקאות'!$A$2:$A$1958,B19)} -> 21001 | G19: {=F19/2} -> 10500.5 | H19: {=_xlfn.SUMIFS('הכנסות'!$D$2:$D$98,'הכנסות'!$A$2:$A$98,B19)} -> 51323 | I19: {=_xlfn.SUMIFS('עסקאות'!$O$2:$O$1958,'עסקאות'!$A$2:$A$1958,B19)} -> 0 | J19: {=H19+I19} -> 51323 | K19: {=J19-E19} -> 24072 | L19: {=IF(J19=0,"",K19/J19)} -> 0.46902948 | M19: {=AVERAGE(F17:F19)} -> 24045.333
B20: 46054 | C20: 2026-02 | D20: סגור | E20: {=_xlfn.SUMIFS('עסקאות'!$M$2:$M$1958,'עסקאות'!$A$2:$A$1958,B20)} -> 26956 | F20: {=_xlfn.SUMIFS('עסקאות'!$N$2:$N$1958,'עסקאות'!$A$2:$A$1958,B20)} -> 20873 | G20: {=F20/2} -> 10436.5 | H20: {=_xlfn.SUMIFS('הכנסות'!$D$2:$D$98,'הכנסות'!$A$2:$A$98,B20)} -> 50650 | I20: {=_xlfn.SUMIFS('עסקאות'!$O$2:$O$1958,'עסקאות'!$A$2:$A$1958,B20)} -> 0 | J20: {=H20+I20} -> 50650 | K20: {=J20-E20} -> 23694 | L20: {=IF(J20=0,"",K20/J20)} -> 0.46779862 | M20: {=AVERAGE(F18:F20)} -> 23616.667
... B26: 46235 | C26: 2026-08 | D26: פתוח | E26: {=_xlfn.SUMIFS('עסקאות'!$M$2:$M$1958,'עסקאות'!$A$2:$A$1958,B26)} -> 34550 | F26: {=_xlfn.SUMIFS('עסקאות'!$N$2:$N$1958,'עסקאות'!$A$2:$A$1958,B26)} -> 26839 | G26: {=F26/2} -> 13419.5 | H26: {=_xlfn.SUMIFS('הכנסות'!$D$2:$D$98,'הכנסות'!$A$2:$A$98,B26)} -> 52225 | I26: {=_xlfn.SUMIFS('עסקאות'!$O$2:$O$1958,'עסקאות'!$A$2:$A$1958,B26)} -> 0 | J26: {=H26+I26} -> 52225 | K26: {=J26-E26} -> 17675 | L26: {=IF(J26=0,"",K26/J26)} -> 0.33843944 | M26: {=AVERAGE(F24:F26)} -> 22871.667

Sheet ניתוח קטגוריות
B2: ניתוח קטגוריות
B3: קטגוריות מקור אוחדו לקבוצות עקב שינוי שמות בין השנים
B6: קבוצה | C6: סיווג | D6: סה״כ (₪) | E6: ממוצע 20 ח׳ (₪) | F6: ממוצע לנפש (₪) | G6: חלק מההוצאה | H6: 2025 סה״כ (₪) | I6: 2025 חודשי (₪) | J6: 2026 סה״כ (₪) | K6: 2026 חודשי (₪) | L6: שינוי חודשי | M6: יעד צמצום | N6: חיסכון חודשי (₪) | O6: חיסכון שנתי (₪) | P6: הערה למומחה
B7: דיור – בית מגורים | C7: שוטף | D7: {=_xlfn.SUMIFS('עסקאות'!$M$2:$M$1958,'עסקאות'!$I$2:$I$1958,B7)} -> 176730 | E7: {=D7/20} -> 8836.5 | F7: {=E7/2} -> 4418.25 | G7: {=IF(SUM($D$7:$D$28)=0,"",D7/SUM($D$7:$D$28))} -> 0.21570722 | H7: {=_xlfn.SUMIFS('עסקאות'!$M$2:$M$1958,'עסקאות'!$I$2:$I$1958,B7,'עסקאות'!$A$2:$A$1958,">="&DATE(2025,1,1),'עסקאות'!$A$2:$A$1958,"<"&DATE(2026,1,1))} -> 97325 | I7: {=H7/12} -> 8110.4167 | J7: {=_xlfn.SUMIFS('עסקאות'!$M$2:$M$1958,'עסקאות'!$I$2:$I$1958,B7,'עסקאות'!$A$2:$A$1958,">="&DATE(2026,1,1),'עסקאות'!$A$2:$A$1958,"<"&DATE(2027,1,1))} -> 79405 | K7: {=J7/8} -> 9925.625 | L7: {=IF(I7=0,"",K7/I7-1)} -> 0.22381197 | M7: {=0} -> 0 | N7: {=IF(C7="שוטף",K7*M7,0)} -> 0 | O7: {=N7*12} -> 0 | P7: הרכיב הגדול ביותר. שכר הדירה עלה מכ־₪6,458 לחודש ב־2025 ל־₪8,000 ב־2026; לבדוק חוזה, תקשורת, ניקיון וצריכת חשמל בנפרד.
B8: נכס להשקעה | C8: חריג/נכס | D8: {=_xlfn.SUMIFS('עסקאות'!$M$2:$M$1958,'עסקאות'!$I$2:$I$1958,B8)} -> 134579 | E8: {=D8/20} -> 6728.95 | F8: {=E8/2} -> 3364.475 | G8: {=IF(SUM($D$7:$D$28)=0,"",D8/SUM($D$7:$D$28))} -> 0.16425995 | H8: {=_xlfn.SUMIFS('עסקאות'!$M$2:$M$1958,'עסקאות'!$I$2:$I$1958,B8,'עסקאות'!$A$2:$A$1958,">="&DATE(2025,1,1),'עסקאות'!$A$2:$A$1958,"<"&DATE(2026,1,1))} -> 80039 | I8: {=H8/12} -> 6669.9167 | J8: {=_xlfn.SUMIFS('עסקאות'!$M$2:$M$1958,'עסקאות'!$I$2:$I$1958,B8,'עסקאות'!$A$2:$A$1958,">="&DATE(2026,1,1),'עסקאות'!$A$2:$A$1958,"<"&DATE(2027,1,1))} -> 54540 | K8: {=J8/8} -> 6817.5 | L8: {=IF(I8=0,"",K8/I8-1)} -> 0.022126713 | M8: {=0} -> 0 | N8: {=IF(C8="שוטף",K8*M8,0)} -> 0 | O8: {=N8*12} -> 0 | P8: לנתח כיחידת רווח והפסד נפרדת. ב־2025 שכר הדירה נרשם כהוצאה שלילית; בקובץ הוא סווג מחדש להכנסה.
B9: נסיעות וחופשות | C9: חריג | D9: {=_xlfn.SUMIFS('עסקאות'!$M$2:$M$1958,'עסקאות'!$I$2:$I$1958,B9)} -> 118704 | E9: {=D9/20} -> 5935.2 | F9: {=E9/2} -> 2967.6 | G9: {=IF(SUM($D$7:$D$28)=0,"",D9/SUM($D$7:$D$28))} -> 0.14488377 | H9: {=_xlfn.SUMIFS('עסקאות'!$M$2:$M$1958,'עסקאות'!$I$2:$I$1958,B9,'עסקאות'!$A$2:$A$1958,">="&DATE(2025,1,1),'עסקאות'!$A$2:$A$1958,"<"&DATE(2026,1,1))} -> 87325 | I9: {=H9/12} -> 7277.0833 | J9: {=_xlfn.SUMIFS('עסקאות'!$M$2:$M$1958,'עסקאות'!$I$2:$I$1958,B9,'עסקאות'!$A$2:$A$1958,">="&DATE(2026,1,1),'עסקאות'!$A$2:$A$1958,"<"&DATE(2027,1,1))} -> 31379 | K9: {=J9/8} -> 3922.375 | L9: {=IF(I9=0,"",K9/I9-1)} -> -0.46099628 | M9: {=0} -> 0 | N9: {=IF(C9="שוטף",K9*M9,0)} -> 0 | O9: {=N9*12} -> 0 | P9: הוצאה מתוכננת ולא שוטפת. מומלץ לקבוע תקציב שנתי וקרן חודשית נפרדת.
B10: חתונה | C10: חריג | D10: {=_xlfn.SUMIFS('עסקאות'!$M$2:$M$1958,'עסקאות'!$I$2:$I$1958,B10)} -> 95615 | E10: {=D10/20} -> 4780.75 | F10: {=E10/2} -> 2390.375 | G10: {=IF(SUM($D$7:$D$28)=0,"",D10/SUM($D$7:$D$28))} -> 0.11670257 | H10: {=_xlfn.SUMIFS('עסקאות'!$M$2:$M$1958,'עסקאות'!$I$2:$I$1958,B10,'עסקאות'!$A$2:$A$1958,">="&DATE(2025,1,1),'עסקאות'!$A$2:$A$1958,"<"&DATE(2026,1,1))} -> 95615 | I10: {=H10/12} -> 7967.9167 | J10: {=_xlfn.SUMIFS('עסקאות'!$M$2:$M$1958,'עסקאות'!$I$2:$I$1958,B10,'עסקאות'!$A$2:$A$1958,">="&DATE(2026,1,1),'עסקאות'!$A$2:$A$1958,"<"&DATE(2027,1,1))} -> 0 | K10: {=J10/8} -> 0 | L10: {=IF(I10=0,"",K10/I10-1)} -> -1 | M10: {=0} -> 0 | N10: {=IF(C10="שוטף",K10*M10,0)} -> 0 | O10: {=N10*12} -> 0 | P10: הוצאה חד־פעמית; הוחרגה ממדד ההוצאה השוטפת.
B11: בריאות וטיפולים | C11: שוטף | D11: {=_xlfn.SUMIFS('עסקאות'!$M$2:$M$1958,'עסקאות'!$I$2:$I$1958,B11)} -> 51681 | E11: {=D11/20} -> 2584.05 | F11: {=E11/2} -> 1292.025 | G11: {=IF(SUM($D$7:$D$28)=0,"",D11/SUM($D$7:$D$28))} -> 0.063079073 | H11: {=_xlfn.SUMIFS('עסקאות'!$M$2:$M$1958,'עסקאות'!$I$2:$I$1958,B11,'עסקאות'!$A$2:$A$1958,">="&DATE(2025,1,1),'עסקאות'!$A$2:$A$1958,"<"&DATE(2026,1,1))} -> 32906 | I11: {=H11/12} -> 2742.1667 | J11: {=_xlfn.SUMIFS('עסקאות'!$M$2:$M$1958,'עסקאות'!$I$2:$I$1958,B11,'עסקאות'!$A$2:$A$1958,">="&DATE(2026,1,1),'עסקאות'!$A$2:$A$1958,"<"&DATE(2027,1,1))} -> 18775 | K11: {=J11/8} -> 2346.875 | L11: {=IF(I11=0,"",K11/I11-1)} -> -0.14415304 | M11: {=0} -> 0 | N11: {=IF(C11="שוטף",K11*M11,0)} -> 0 | O11: {=N11*12} -> 0 | P11: לא מומלץ לקצץ טיפול. לבדוק החזרים משב״ן/ביטוח וכפל כיסויים.
B12: מזון לבית | C12: שוטף | D12: {=_xlfn.SUMIFS('עסקאות'!$M$2:$M$1958,'עסקאות'!$I$2:$I$1958,B12)} -> 41741 | E12: {=D12/20} -> 2087.05 | F12: {=E12/2} -> 1043.525 | G12: {=IF(SUM($D$7:$D$28)=0,"",D12/SUM($D$7:$D$28))} -> 0.050946839 | H12: {=_xlfn.SUMIFS('עסקאות'!$M$2:$M$1958,'עסקאות'!$I$2:$I$1958,B12,'עסקאות'!$A$2:$A$1958,">="&DATE(2025,1,1),'עסקאות'!$A$2:$A$1958,"<"&DATE(2026,1,1))} -> 24837 | I12: {=H12/12} -> 2069.75 | J12: {=_xlfn.SUMIFS('עסקאות'!$M$2:$M$1958,'עסקאות'!$I$2:$I$1958,B12,'עסקאות'!$A$2:$A$1958,">="&DATE(2026,1,1),'עסקאות'!$A$2:$A$1958,"<"&DATE(2027,1,1))} -> 16904 | K12: {=J12/8} -> 2113 | L12: {=IF(I12=0,"",K12/I12-1)} -> 0.020896244 | M12: {=0.03} -> 0.03 | N12: {=IF(C12="שוטף",K12*M12,0)} -> 63.39 | O12: {=N12*12} -> 760.68 | P12: רשימת קניות קבועה, איחוד קניות והשוואה חודשית בין סלים.
B13: ספורט | C13: שוטף | D13: {=_xlfn.SUMIFS('עסקאות'!$M$2:$M$1958,'עסקאות'!$I$2:$I$1958,B13)} -> 38331 | E13: {=D13/20} -> 1916.55 | F13: {=E13/2} -> 958.275 | G13: {=IF(SUM($D$7:$D$28)=0,"",D13/SUM($D$7:$D$28))} -> 0.046784775 | H13: {=_xlfn.SUMIFS('עסקאות'!$M$2:$M$1958,'עסקאות'!$I$2:$I$1958,B13,'עסקאות'!$A$2:$A$1958,">="&DATE(2025,1,1),'עסקאות'!$A$2:$A$1958,"<"&DATE(2026,1,1))} -> 25610 | I13: {=H13/12} -> 2134.1667 | J13: {=_xlfn.SUMIFS('עסקאות'!$M$2:$M$1958,'עסקאות'!$I$2:$I$1958,B13,'עסקאות'!$A$2:$A$1958,">="&DATE(2026,1,1),'עסקאות'!$A$2:$A$1958,"<"&DATE(2027,1,1))} -> 12721 | K13: {=J13/8} -> 1590.125 | L13: {=IF(I13=0,"",K13/I13-1)} -> -0.25491995 | M13: {=0.05} -> 0.05 | N13: {=IF(C13="שוטף",K13*M13,0)} -> 79.50625 | O13: {=N13*12} -> 954.075 | P13: בדיקת חפיפה בין קאנטרי, אימונים פרטיים וחבילות; לא לצמצם פעילות.
B14: אוכל בחוץ | C14: שוטף | D14: {=_xlfn.SUMIFS('עסקאות'!$M$2:$M$1958,'עסקאות'!$I$2:$I$1958,B14)} -> 30226 | E14: {=D14/20} -> 1511.3 | F14: {=E14/2} -> 755.65 | G14: {=IF(SUM($D$7:$D$28)=0,"",D14/SUM($D$7:$D$28))} -> 0.036892244 | H14: {=_xlfn.SUMIFS('עסקאות'!$M$2:$M$1958,'עסקאות'!$I$2:$I$1958,B14,'עסקאות'!$A$2:$A$1958,">="&DATE(2025,1,1),'עסקאות'!$A$2:$A$1958,"<"&DATE(2026,1,1))} -> 17724 | I14: {=H14/12} -> 1477 | J14: {=_xlfn.SUMIFS('עסקאות'!$M$2:$M$1958,'עסקאות'!$I$2:$I$1958,B14,'עסקאות'!$A$2:$A$1958,">="&DATE(2026,1,1),'עסקאות'!$A$2:$A$1958,"<"&DATE(2027,1,1))} -> 12502 | K14: {=J14/8} -> 1562.75 | L14: {=IF(I14=0,"",K14/I14-1)} -> 0.058056872 | M14: {=0.07} -> 0.07 | N14: {=IF(C14="שוטף",K14*M14,0)} -> 109.3925 | O14: {=N14*12} -> 1312.71 | P14: תקציב שבועי קבוע ושימוש מלא בהטבות אוכל לפני תשלום פרטי.
B15: תחבורה | C15: שוטף | D15: {=_xlfn.SUMIFS('עסקאות'!$M$2:$M$1958,'עסקאות'!$I$2:$I$1958,B15)} -> 25185 | E15: {=D15/20} -> 1259.25 | F15: {=E15/2} -> 629.625 | G15: {=IF(SUM($D$7:$D$28)=0,"",D15/SUM($D$7:$D$28))} -> 0.030739468 | H15: {=_xlfn.SUMIFS('עסקאות'!$M$2:$M$1958,'עסקאות'!$I$2:$I$1958,B15,'עסקאות'!$A$2:$A$1958,">="&DATE(2025,1,1),'עסקאות'!$A$2:$A$1958,"<"&DATE(2026,1,1))} -> 16347 | I15: {=H15/12} -> 1362.25 | J15: {=_xlfn.SUMIFS('עסקאות'!$M$2:$M$1958,'עסקאות'!$I$2:$I$1958,B15,'עסקאות'!$A$2:$A$1958,">="&DATE(2026,1,1),'עסקאות'!$A$2:$A$1958,"<"&DATE(2027,1,1))} -> 8838 | K15: {=J15/8} -> 1104.75 | L15: {=IF(I15=0,"",K15/I15-1)} -> -0.18902551 | M15: {=0.03} -> 0.03 | N15: {=IF(C15="שוטף",K15*M15,0)} -> 33.1425 | O15: {=N15*12} -> 397.71 | P15: תדלוק מתוכנן, איחוד נסיעות ובדיקת כיסוי ביטוחי פעם בשנה.
B16: קניות לבית | C16: שוטף | D16: {=_xlfn.SUMIFS('עסקאות'!$M$2:$M$1958,'עסקאות'!$I$2:$I$1958,B16)} -> 20138 | E16: {=D16/20} -> 1006.9 | F16: {=E16/2} -> 503.45 | G16: {=IF(SUM($D$7:$D$28)=0,"",D16/SUM($D$7:$D$28))} -> 0.024579369 | H16: {=_xlfn.SUMIFS('עסקאות'!$M$2:$M$1958,'עסקאות'!$I$2:$I$1958,B16,'עסקאות'!$A$2:$A$1958,">="&DATE(2025,1,1),'עסקאות'!$A$2:$A$1958,"<"&DATE(2026,1,1))} -> 15288 | I16: {=H16/12} -> 1274 | J16: {=_xlfn.SUMIFS('עסקאות'!$M$2:$M$1958,'עסקאות'!$I$2:$I$1958,B16,'עסקאות'!$A$2:$A$1958,">="&DATE(2026,1,1),'עסקאות'!$A$2:$A$1958,"<"&DATE(2027,1,1))} -> 4850 | K16: {=J16/8} -> 606.25 | L16: {=IF(I16=0,"",K16/I16-1)} -> -0.52413658 | M16: {=0.07} -> 0.07 | N16: {=IF(C16="שוטף",K16*M16,0)} -> 42.4375 | O16: {=N16*12} -> 509.25 | P16: חלון המתנה של 48 שעות ורשימת רכישות חודשית מאוחדת.
B17: מסים | C17: חריג | D17: {=_xlfn.SUMIFS('עסקאות'!$M$2:$M$1958,'עסקאות'!$I$2:$I$1958,B17)} -> 18826 | E17: {=D17/20} -> 941.3 | F17: {=E17/2} -> 470.65 | G17: {=IF(SUM($D$7:$D$28)=0,"",D17/SUM($D$7:$D$28))} -> 0.022978012 | H17: {=_xlfn.SUMIFS('עסקאות'!$M$2:$M$1958,'עסקאות'!$I$2:$I$1958,B17,'עסקאות'!$A$2:$A$1958,">="&DATE(2025,1,1),'עסקאות'!$A$2:$A$1958,"<"&DATE(2026,1,1))} -> 0 | I17: {=H17/12} -> 0 | J17: {=_xlfn.SUMIFS('עסקאות'!$M$2:$M$1958,'עסקאות'!$I$2:$I$1958,B17,'עסקאות'!$A$2:$A$1958,">="&DATE(2026,1,1),'עסקאות'!$A$2:$A$1958,"<"&DATE(2027,1,1))} -> 18826 | K17: {=J17/8} -> 2353.25 | L17: {=IF(I17=0,"",K17/I17-1)} | M17: {=0} -> 0 | N17: {=IF(C17="שוטף",K17*M17,0)} -> 0 | O17: {=N17*12} -> 0 | P17: הוצאה חריגה; לבדוק מול רו״ח אם היא חד־פעמית או צפויה לחזור.
B18: פנאי | C18: שוטף | D18: {=_xlfn.SUMIFS('עסקאות'!$M$2:$M$1958,'עסקאות'!$I$2:$I$1958,B18)} -> 11671 | E18: {=D18/20} -> 583.55 | F18: {=E18/2} -> 291.775 | G18: {=IF(SUM($D$7:$D$28)=0,"",D18/SUM($D$7:$D$28))} -> 0.014245 | H18: {=_xlfn.SUMIFS('עסקאות'!$M$2:$M$1958,'עסקאות'!$I$2:$I$1958,B18,'עסקאות'!$A$2:$A$1958,">="&DATE(2025,1,1),'עסקאות'!$A$2:$A$1958,"<"&DATE(2026,1,1))} -> 9397 | I18: {=H18/12} -> 783.08333 | J18: {=_xlfn.SUMIFS('עסקאות'!$M$2:$M$1958,'עסקאות'!$I$2:$I$1958,B18,'עסקאות'!$A$2:$A$1958,">="&DATE(2026,1,1),'עסקאות'!$A$2:$A$1958,"<"&DATE(2027,1,1))} -> 2274 | K18: {=J18/8} -> 284.25 | L18: {=IF(I18=0,"",K18/I18-1)} -> -0.63701181 | M18: {=0.07} -> 0.07 | N18: {=IF(C18="שוטף",K18*M18,0)} -> 19.8975 | O18: {=N18*12} -> 238.77 | P18: תקרה חודשית מתגלגלת בלי לבטל פעילויות קבועות.
B19: אופנה | C19: שוטף | D19: {=_xlfn.SUMIFS('עסקאות'!$M$2:$M$1958,'עסקאות'!$I$2:$I$1958,B19)} -> 10790 | E19: {=D19/20} -> 539.5 | F19: {=E19/2} -> 269.75 | G19: {=IF(SUM($D$7:$D$28)=0,"",D19/SUM($D$7:$D$28))} -> 0.013169699 | H19: {=_xlfn.SUMIFS('עסקאות'!$M$2:$M$1958,'עסקאות'!$I$2:$I$1958,B19,'עסקאות'!$A$2:$A$1958,">="&DATE(2025,1,1),'עסקאות'!$A$2:$A$1958,"<"&DATE(2026,1,1))} -> 7355 | I19: {=H19/12} -> 612.91667 | J19: {=_xlfn.SUMIFS('עסקאות'!$M$2:$M$1958,'עסקאות'!$I$2:$I$1958,B19,'עסקאות'!$A$2:$A$1958,">="&DATE(2026,1,1),'עסקאות'!$A$2:$A$1958,"<"&DATE(2027,1,1))} -> 3435 | K19: {=J19/8} -> 429.375 | L19: {=IF(I19=0,"",K19/I19-1)} -> -0.29945615 | M19: {=0.07} -> 0.07 | N19: {=IF(C19="שוטף",K19*M19,0)} -> 30.05625 | O19: {=N19*12} -> 360.675 | P19: תקרת קנייה חודשית נטו אחרי החזרות.
B20: מתנה | C20: שוטף | D20: {=_xlfn.SUMIFS('עסקאות'!$M$2:$M$1958,'עסקאות'!$I$2:$I$1958,B20)} -> 10572 | E20: {=D20/20} -> 528.6 | F20: {=E20/2} -> 264.3 | G20: {=IF(SUM($D$7:$D$28)=0,"",D20/SUM($D$7:$D$28))} -> 0.01290362 | H20: {=_xlfn.SUMIFS('עסקאות'!$M$2:$M$1958,'עסקאות'!$I$2:$I$1958,B20,'עסקאות'!$A$2:$A$1958,">="&DATE(2025,1,1),'עסקאות'!$A$2:$A$1958,"<"&DATE(2026,1,1))} -> 4345 | I20: {=H20/12} -> 362.08333 | J20: {=_xlfn.SUMIFS('עסקאות'!$M$2:$M$1958,'עסקאות'!$I$2:$I$1958,B20,'עסקאות'!$A$2:$A$1958,">="&DATE(2026,1,1),'עסקאות'!$A$2:$A$1958,"<"&DATE(2027,1,1))} -> 6227 | K20: {=J20/8} -> 778.375 | L20: {=IF(I20=0,"",K20/I20-1)} -> 1.1497123 | M20: {=0.07} -> 0.07 | N20: {=IF(C20="שוטף",K20*M20,0)} -> 54.48625 | O20: {=N20*12} -> 653.835 | P20: קרן שנתית לאירועים כדי להחליק חודשים יקרים.
B21: קוסמטיקה | C21: שוטף | D21: {=_xlfn.SUMIFS('עסקאות'!$M$2:$M$1958,'עסקאות'!$I$2:$I$1958,B21)} -> 8307 | E21: {=D21/20} -> 415.35 | F21: {=E21/2} -> 207.675 | G21: {=IF(SUM($D$7:$D$28)=0,"",D21/SUM($D$7:$D$28))} -> 0.010139081 | H21: {=_xlfn.SUMIFS('עסקאות'!$M$2:$M$1958,'עסקאות'!$I$2:$I$1958,B21,'עסקאות'!$A$2:$A$1958,">="&DATE(2025,1,1),'עסקאות'!$A$2:$A$1958,"<"&DATE(2026,1,1))} -> 5736 | I21: {=H21/12} -> 478 | J21: {=_xlfn.SUMIFS('עסקאות'!$M$2:$M$1958,'עסקאות'!$I$2:$I$1958,B21,'עסקאות'!$A$2:$A$1958,">="&DATE(2026,1,1),'עסקאות'!$A$2:$A$1958,"<"&DATE(2027,1,1))} -> 2571 | K21: {=J21/8} -> 321.375 | L21: {=IF(I21=0,"",K21/I21-1)} -> -0.32766736 | M21: {=0.07} -> 0.07 | N21: {=IF(C21="שוטף",K21*M21,0)} -> 22.49625 | O21: {=N21*12} -> 269.955 | P21: ריכוז טיפולים ורכישות ובדיקת חבילות/הנחות.
B22: אחר | C22: שוטף | D22: {=_xlfn.SUMIFS('עסקאות'!$M$2:$M$1958,'עסקאות'!$I$2:$I$1958,B22)} -> 7955 | E22: {=D22/20} -> 397.75 | F22: {=E22/2} -> 198.875 | G22: {=IF(SUM($D$7:$D$28)=0,"",D22/SUM($D$7:$D$28))} -> 0.0097094489 | H22: {=_xlfn.SUMIFS('עסקאות'!$M$2:$M$1958,'עסקאות'!$I$2:$I$1958,B22,'עסקאות'!$A$2:$A$1958,">="&DATE(2025,1,1),'עסקאות'!$A$2:$A$1958,"<"&DATE(2026,1,1))} -> 7955 | I22: {=H22/12} -> 662.91667 | J22: {=_xlfn.SUMIFS('עסקאות'!$M$2:$M$1958,'עסקאות'!$I$2:$I$1958,B22,'עסקאות'!$A$2:$A$1958,">="&DATE(2026,1,1),'עסקאות'!$A$2:$A$1958,"<"&DATE(2027,1,1))} -> 0 | K22: {=J22/8} -> 0 | L22: {=IF(I22=0,"",K22/I22-1)} -> -1 | M22: {=0} -> 0 | N22: {=IF(C22="שוטף",K22*M22,0)} -> 0 | O22: {=N22*12} -> 0 | P22: לבחון לפי סדרי העדיפויות של משק הבית.
B23: תחביבים ומיג'י | C23: שוטף | D23: {=_xlfn.SUMIFS('עסקאות'!$M$2:$M$1958,'עסקאות'!$I$2:$I$1958,B23)} -> 7297 | E23: {=D23/20} -> 364.85 | F23: {=E23/2} -> 182.425 | G23: {=IF(SUM($D$7:$D$28)=0,"",D23/SUM($D$7:$D$28))} -> 0.0089063291 | H23: {=_xlfn.SUMIFS('עסקאות'!$M$2:$M$1958,'עסקאות'!$I$2:$I$1958,B23,'עסקאות'!$A$2:$A$1958,">="&DATE(2025,1,1),'עסקאות'!$A$2:$A$1958,"<"&DATE(2026,1,1))} -> 1064 | I23: {=H23/12} -> 88.666667 | J23: {=_xlfn.SUMIFS('עסקאות'!$M$2:$M$1958,'עסקאות'!$I$2:$I$1958,B23,'עסקאות'!$A$2:$A$1958,">="&DATE(2026,1,1),'עסקאות'!$A$2:$A$1958,"<"&DATE(2027,1,1))} -> 6233 | K23: {=J23/8} -> 779.125 | L23: {=IF(I23=0,"",K23/I23-1)} -> 7.7871241 | M23: {=0} -> 0 | N23: {=IF(C23="שוטף",K23*M23,0)} -> 0 | O23: {=N23*12} -> 0 | P23: נדרש להסביר למומחה מה כוללת הקטגוריה לפני קביעת יעד.
B24: אלקטרוניקה | C24: שוטף | D24: {=_xlfn.SUMIFS('עסקאות'!$M$2:$M$1958,'עסקאות'!$I$2:$I$1958,B24)} -> 6498 | E24: {=D24/20} -> 324.9 | F24: {=E24/2} -> 162.45 | G24: {=IF(SUM($D$7:$D$28)=0,"",D24/SUM($D$7:$D$28))} -> 0.0079311123 | H24: {=_xlfn.SUMIFS('עסקאות'!$M$2:$M$1958,'עסקאות'!$I$2:$I$1958,B24,'עסקאות'!$A$2:$A$1958,">="&DATE(2025,1,1),'עסקאות'!$A$2:$A$1958,"<"&DATE(2026,1,1))} -> 3513 | I24: {=H24/12} -> 292.75 | J24: {=_xlfn.SUMIFS('עסקאות'!$M$2:$M$1958,'עסקאות'!$I$2:$I$1958,B24,'עסקאות'!$A$2:$A$1958,">="&DATE(2026,1,1),'עסקאות'!$A$2:$A$1958,"<"&DATE(2027,1,1))} -> 2985 | K24: {=J24/8} -> 373.125 | L24: {=IF(I24=0,"",K24/I24-1)} -> 0.27455167 | M24: {=0.07} -> 0.07 | N24: {=IF(C24="שוטף",K24*M24,0)} -> 26.11875 | O24: {=N24*12} -> 313.425 | P24: קרן חודשית לרכישות גדולות במקום רכישות אד-הוק.
B25: ביטוח | C25: שוטף | D25: {=_xlfn.SUMIFS('עסקאות'!$M$2:$M$1958,'עסקאות'!$I$2:$I$1958,B25)} -> 2216 | E25: {=D25/20} -> 110.8 | F25: {=E25/2} -> 55.4 | G25: {=IF(SUM($D$7:$D$28)=0,"",D25/SUM($D$7:$D$28))} -> 0.0027047314 | H25: {=_xlfn.SUMIFS('עסקאות'!$M$2:$M$1958,'עסקאות'!$I$2:$I$1958,B25,'עסקאות'!$A$2:$A$1958,">="&DATE(2025,1,1),'עסקאות'!$A$2:$A$1958,"<"&DATE(2026,1,1))} -> 1024 | I25: {=H25/12} -> 85.333333 | J25: {=_xlfn.SUMIFS('עסקאות'!$M$2:$M$1958,'עסקאות'!$I$2:$I$1958,B25,'עסקאות'!$A$2:$A$1958,">="&DATE(2026,1,1),'עסקאות'!$A$2:$A$1958,"<"&DATE(2027,1,1))} -> 1192 | K25: {=J25/8} -> 149 | L25: {=IF(I25=0,"",K25/I25-1)} -> 0.74609375 | M25: {=0.05} -> 0.05 | N25: {=IF(C25="שוטף",K25*M25,0)} -> 7.45 | O25: {=N25*12} -> 89.4 | P25: בדיקת כפילויות וכיסויים לפני חידוש; לא לבטל ללא בדיקה מקצועית.
B26: לא מסווג | C26: שוטף | D26: {=_xlfn.SUMIFS('עסקאות'!$M$2:$M$1958,'עסקאות'!$I$2:$I$1958,B26)} -> 1959 | E26: {=D26/20} -> 97.95 | F26: {=E26/2} -> 48.975 | G26: {=IF(SUM($D$7:$D$28)=0,"",D26/SUM($D$7:$D$28))} -> 0.002391051 | H26: {=_xlfn.SUMIFS('עסקאות'!$M$2:$M$1958,'עסקאות'!$I$2:$I$1958,B26,'עסקאות'!$A$2:$A$1958,">="&DATE(2025,1,1),'עסקאות'!$A$2:$A$1958,"<"&DATE(2026,1,1))} -> 0 | I26: {=H26/12} -> 0 | J26: {=_xlfn.SUMIFS('עסקאות'!$M$2:$M$1958,'עסקאות'!$I$2:$I$1958,B26,'עסקאות'!$A$2:$A$1958,">="&DATE(2026,1,1),'עסקאות'!$A$2:$A$1958,"<"&DATE(2027,1,1))} -> 1959 | K26: {=J26/8} -> 244.875 | L26: {=IF(I26=0,"",K26/I26-1)} | M26: {=0} -> 0 | N26: {=IF(C26="שוטף",K26*M26,0)} -> 0 | O26: {=N26*12} -> 0 | P26: יש לסווג לפני קבלת החלטות; רוב הסכום נובע מרשומה אחת בסך ₪1,800.
B27: עמלות | C27: שוטף | D27: {=_xlfn.SUMIFS('עסקאות'!$M$2:$M$1958,'עסקאות'!$I$2:$I$1958,B27)} -> 284 | E27: {=D27/20} -> 14.2 | F27: {=E27/2} -> 7.1 | G27: {=IF(SUM($D$7:$D$28)=0,"",D27/SUM($D$7:$D$28))} -> 0.00034663526 | H27: {=_xlfn.SUMIFS('עסקאות'!$M$2:$M$1958,'עסקאות'!$I$2:$I$1958,B27,'עסקאות'!$A$2:$A$1958,">="&DATE(2025,1,1),'עסקאות'!$A$2:$A$1958,"<"&DATE(2026,1,1))} -> 282 | I27: {=H27/12} -> 23.5 | J27: {=_xlfn.SUMIFS('עסקאות'!$M$2:$M$1958,'עסקאות'!$I$2:$I$1958,B27,'עסקאות'!$A$2:$A$1958,">="&DATE(2026,1,1),'עסקאות'!$A$2:$A$1958,"<"&DATE(2027,1,1))} -> 2 | K27: {=J27/8} -> 0.25 | L27: {=IF(I27=0,"",K27/I27-1)} -> -0.9893617 | M27: {=0.2} -> 0.2 | N27: {=IF(C27="שוטף",K27*M27,0)} -> 0.05 | O27: {=N27*12} -> 0.6 | P27: בדיקת מסלול עמלות ותנאי כרטיסים; הסכום קטן אך קל לטיפול.
B28: זרם פיננסי | C28: הכנסה שסווגה מחדש | D28: {=_xlfn.SUMIFS('עסקאות'!$M$2:$M$1958,'עסקאות'!$I$2:$I$1958,B28)} -> 0 | E28: {=D28/20} -> 0 | F28: {=E28/2} -> 0 | G28: {=IF(SUM($D$7:$D$28)=0,"",D28/SUM($D$7:$D$28))} -> 0 | H28: {=_xlfn.SUMIFS('עסקאות'!$M$2:$M$1958,'עסקאות'!$I$2:$I$1958,B28,'עסקאות'!$A$2:$A$1958,">="&DATE(2025,1,1),'עסקאות'!$A$2:$A$1958,"<"&DATE(2026,1,1))} -> 0 | I28: {=H28/12} -> 0 | J28: {=_xlfn.SUMIFS('עסקאות'!$M$2:$M$1958,'עסקאות'!$I$2:$I$1958,B28,'עסקאות'!$A$2:$A$1958,">="&DATE(2026,1,1),'עסקאות'!$A$2:$A$1958,"<"&DATE(2027,1,1))} -> 0 | K28: {=J28/8} -> 0 | L28: {=IF(I28=0,"",K28/I28-1)} | M28: {=0} -> 0 | N28: {=IF(C28="שוטף",K28*M28,0)} -> 0 | O28: {=N28*12} -> 0 | P28: ריביות והכנסות שנרשמו בסימן שלילי בצד ההוצאות; אינן הוצאה צרכנית.

Sheet המלצות
B2: המלצות להכנה לפגישת מומחה
B3: החיסכון הוא תרחיש שמרני המבוסס על ממוצע היסטורי; שיעורי היעד בכחול וניתנים לשינוי
B6: תחום | C6: בסיס חודשי (₪) | D6: יעד נמוך | E6: יעד גבוה | F6: חיסכון נמוך (₪) | G6: חיסכון גבוה (₪) | H6: שנתי נמוך (₪) | I6: שנתי גבוה (₪) | J6: פעולה ללא פגיעה מהותית
B7: אוכל בחוץ | C7: 1511.3 | D7: 0.07 | E7: 0.12 | F7: {=C7*D7} -> 105.791 | G7: {=C7*E7} -> 181.356 | H7: {=F7*12} -> 1269.492 | I7: {=G7*12} -> 2176.272 | J7: תקציב שבועי ושימוש מלא בהטבות לפני תשלום פרטי.
B8: מזון לבית | C8: 2087.05 | D8: 0.03 | E8: 0.06 | F8: {=C8*D8} -> 62.6115 | G8: {=C8*E8} -> 125.223 | H8: {=F8*12} -> 751.338 | I8: {=G8*12} -> 1502.676 | J8: איחוד קניות, רשימה קבועה והשוואת סל פעם בחודש.
B9: ספורט | C9: 1916.55 | D9: 0.05 | E9: 0.12 | F9: {=C9*D9} -> 95.8275 | G9: {=C9*E9} -> 229.986 | H9: {=F9*12} -> 1149.93 | I9: {=G9*12} -> 2759.832 | J9: לשמור על הפעילות ולבדוק חפיפה בין קאנטרי, מאמנים וחבילות.
B10: קניות, פנאי ואופנה | C10: 3398.8 | D10: 0.07 | E10: 0.12 | F10: {=C10*D10} -> 237.916 | G10: {=C10*E10} -> 407.856 | H10: {=F10*12} -> 2854.992 | I10: {=G10*12} -> 4894.272 | J10: תקרה חודשית משותפת עם יתרה מתגלגלת וחלון המתנה לרכישות.
B11: ניקיון | C11: {=_xlfn.SUMIFS('עסקאות'!$M$2:$M$1958,'עסקאות'!$F$2:$F$1958,"מנקה")/20} -> 523 | D11: 0.05 | E11: 0.15 | F11: {=C11*D11} -> 26.15 | G11: {=C11*E11} -> 78.45 | H11: {=F11*12} -> 313.8 | I11: {=G11*12} -> 941.4 | J11: בדיקת תדירות או משך ביקור, בלי לוותר על השירות.
B12: תחבורה | C12: 1259.25 | D12: 0.03 | E12: 0.07 | F12: {=C12*D12} -> 37.7775 | G12: {=C12*E12} -> 88.1475 | H12: {=F12*12} -> 453.33 | I12: {=G12*12} -> 1057.77 | J12: תדלוק מתוכנן, איחוד נסיעות ובדיקת ביטוח בחידוש.
B13: ביטוחים ועמלות | C13: 125 | D13: 0.05 | E13: 0.15 | F13: {=C13*D13} -> 6.25 | G13: {=C13*E13} -> 18.75 | H13: {=F13*12} -> 75 | I13: {=G13*12} -> 225 | J13: השוואת מסלולים וכפילויות; לא לבטל כיסוי ללא בדיקה מקצועית.
B14: תקשורת | C14: {=(_xlfn.SUMIFS('עסקאות'!$M$2:$M$1958,'עסקאות'!$F$2:$F$1958,"אינטרנט")+_xlfn.SUMIFS('עסקאות'!$M$2:$M$1958,'עסקאות'!$F$2:$F$1958,"סלולר")+_xlfn.SUMIFS('עסקאות'!$M$2:$M$1958,'עסקאות'!$F$2:$F$1958,"סלולר + אינטרנט"))/20} -> 152.1 | D14: 0.1 | E14: 0.2 | F14: {=C14*D14} -> 15.21 | G14: {=C14*E14} -> 30.42 | H14: {=F14*12} -> 182.52 | I14: {=G14*12} -> 365.04 | J14: סקר מחיר וחידוש הטבות אחת לשנה.
B15: סה״כ תרחיש | F15: {=SUM(F7:F14)} -> 587.5335 | G15: {=SUM(G7:G14)} -> 1160.1885 | H15: {=SUM(H7:H14)} -> 7050.402 | I15: {=SUM(I7:I14)} -> 13922.262 | J15: היעדים הם נקודת פתיחה לדיון, לא הוראה אוטומטית לקיצוץ.
B18: נושא לבדיקה | C18: סכום/בסיס | D18: למה חשוב | E18: מה לבקש מהמומחה
B19: בריאות וטיפולים | C19: 2584.05 | D19: לא לקצץ טיפול | E19: בדיקת החזרים, שב״ן וכפל ביטוח
B20: דיור | C20: 8836.5 | D20: ההוצאה המבנית הגדולה ביותר | E20: פירוק שכר דירה, ניקיון, תקשורת וחשבונות
B21: נכס להשקעה | C21: 134579 | D21: דורש רווח והפסד נפרד | E21: תשואה נטו, מימון, תחזוקה ומיסוי
B22: לא מסווג | C22: 1959 | D22: אי אפשר להמליץ בלי להבין את הסכום | E22: להשלים סיווג לפני הפגישה
B23: תחביבים ומיג'י | C23: 364.85 | D23: הקטגוריה אינה מוסברת | E23: להגדיר מה חיוני ומה גמיש

Sheet בתי עסק
B2: ניתוח בתי עסק ותיאורים
B3: הקיבוץ הוא לפי תיאור מדויק; שמות דומים עלולים להופיע בשורות נפרדות
B6: תיאור | C6: קבוצה עיקרית | D6: מספר עסקאות | E6: חודשים פעילים | F6: סה״כ (₪) | G6: ממוצע לעסקה (₪) | H6: ממוצע חודשי (₪) | I6: 2025 (₪) | J6: 2026 (₪)
B7: שכר דירה | C7: דיור – בית מגורים | D7: 18 | E7: 18 | F7: {=_xlfn.SUMIFS('עסקאות'!$M$2:$M$1958,'עסקאות'!$F$2:$F$1958,B7)} -> 141500 | G7: {=IF(D7=0,"",F7/D7)} -> 7861.1111 | H7: {=F7/20} -> 7075 | I7: {=_xlfn.SUMIFS('עסקאות'!$M$2:$M$1958,'עסקאות'!$F$2:$F$1958,B7,'עסקאות'!$A$2:$A$1958,">="&DATE(2025,1,1),'עסקאות'!$A$2:$A$1958,"<"&DATE(2026,1,1))} -> 77500 | J7: {=_xlfn.SUMIFS('עסקאות'!$M$2:$M$1958,'עסקאות'!$F$2:$F$1958,B7,'עסקאות'!$A$2:$A$1958,">="&DATE(2026,1,1),'עסקאות'!$A$2:$A$1958,"<"&DATE(2027,1,1))} -> 64000
B8: משכנתא | C8: נכס להשקעה | D8: 20 | E8: 20 | F8: {=_xlfn.SUMIFS('עסקאות'!$M$2:$M$1958,'עסקאות'!$F$2:$F$1958,B8)} -> 122792 | G8: {=IF(D8=0,"",F8/D8)} -> 6139.6 | H8: {=F8/20} -> 6139.6 | I8: {=_xlfn.SUMIFS('עסקאות'!$M$2:$M$1958,'עסקאות'!$F$2:$F$1958,B8,'עסקאות'!$A$2:$A$1958,">="&DATE(2025,1,1),'עסקאות'!$A$2:$A$1958,"<"&DATE(2026,1,1))} -> 73618 | J8: {=_xlfn.SUMIFS('עסקאות'!$M$2:$M$1958,'עסקאות'!$F$2:$F$1958,B8,'עסקאות'!$A$2:$A$1958,">="&DATE(2026,1,1),'עסקאות'!$A$2:$A$1958,"<"&DATE(2027,1,1))} -> 49174
B9: חלי | C9: חתונה | D9: 1 | E9: 1 | F9: {=_xlfn.SUMIFS('עסקאות'!$M$2:$M$1958,'עסקאות'!$F$2:$F$1958,B9)} -> 32471 | G9: {=IF(D9=0,"",F9/D9)} -> 32471 | H9: {=F9/20} -> 1623.55 | I9: {=_xlfn.SUMIFS('עסקאות'!$M$2:$M$1958,'עסקאות'!$F$2:$F$1958,B9,'עסקאות'!$A$2:$A$1958,">="&DATE(2025,1,1),'עסקאות'!$A$2:$A$1958,"<"&DATE(2026,1,1))} -> 32471 | J9: {=_xlfn.SUMIFS('עסקאות'!$M$2:$M$1958,'עסקאות'!$F$2:$F$1958,B9,'עסקאות'!$A$2:$A$1958,">="&DATE(2026,1,1),'עסקאות'!$A$2:$A$1958,"<"&DATE(2027,1,1))} -> 0
B10: ליאת | C10: בריאות וטיפולים | D10: 19 | E10: 19 | F10: {=_xlfn.SUMIFS('עסקאות'!$M$2:$M$1958,'עסקאות'!$F$2:$F$1958,B10)} -> 31050 | G10: {=IF(D10=0,"",F10/D10)} -> 1634.2105 | H10: {=F10/20} -> 1552.5 | I10: {=_xlfn.SUMIFS('עסקאות'!$M$2:$M$1958,'עסקאות'!$F$2:$F$1958,B10,'עסקאות'!$A$2:$A$1958,">="&DATE(2025,1,1),'עסקאות'!$A$2:$A$1958,"<"&DATE(2026,1,1))} -> 16650 | J10: {=_xlfn.SUMIFS('עסקאות'!$M$2:$M$1958,'עסקאות'!$F$2:$F$1958,B10,'עסקאות'!$A$2:$A$1958,">="&DATE(2026,1,1),'עסקאות'!$A$2:$A$1958,"<"&DATE(2027,1,1))} -> 14400
B11: סופר | C11: מזון לבית | D11: 221 | E11: 20 | F11: {=_xlfn.SUMIFS('עסקאות'!$M$2:$M$1958,'עסקאות'!$F$2:$F$1958,B11)} -> 29703 | G11: {=IF(D11=0,"",F11/D11)} -> 134.40271 | H11: {=F11/20} -> 1485.15 | I11: {=_xlfn.SUMIFS('עסקאות'!$M$2:$M$1958,'עסקאות'!$F$2:$F$1958,B11,'עסקאות'!$A$2:$A$1958,">="&DATE(2025,1,1),'עסקאות'!$A$2:$A$1958,"<"&DATE(2026,1,1))} -> 15422 | J11: {=_xlfn.SUMIFS('עסקאות'!$M$2:$M$1958,'עסקאות'!$F$2:$F$1958,B11,'עסקאות'!$A$2:$A$1958,">="&DATE(2026,1,1),'עסקאות'!$A$2:$A$1958,"<"&DATE(2027,1,1))} -> 14281
B12: יפן | C12: נסיעות וחופשות | D12: 7 | E12: 3 | F12: {=_xlfn.SUMIFS('עסקאות'!$M$2:$M$1958,'עסקאות'!$F$2:$F$1958,B12)} -> 20825 | G12: {=IF(D12=0,"",F12/D12)} -> 2975 | H12: {=F12/20} -> 1041.25 | I12: {=_xlfn.SUMIFS('עסקאות'!$M$2:$M$1958,'עסקאות'!$F$2:$F$1958,B12,'עסקאות'!$A$2:$A$1958,">="&DATE(2025,1,1),'עסקאות'!$A$2:$A$1958,"<"&DATE(2026,1,1))} -> 20825 | J12: {=_xlfn.SUMIFS('עסקאות'!$M$2:$M$1958,'עסקאות'!$F$2:$F$1958,B12,'עסקאות'!$A$2:$A$1958,">="&DATE(2026,1,1),'עסקאות'!$A$2:$A$1958,"<"&DATE(2027,1,1))} -> 0
B13: מס יסף | C13: מסים | D13: 1 | E13: 1 | F13: {=_xlfn.SUMIFS('עסקאות'!$M$2:$M$1958,'עסקאות'!$F$2:$F$1958,B13)} -> 16703 | G13: {=IF(D13=0,"",F13/D13)} -> 16703 | H13: {=F13/20} -> 835.15 | I13: {=_xlfn.SUMIFS('עסקאות'!$M$2:$M$1958,'עסקאות'!$F$2:$F$1958,B13,'עסקאות'!$A$2:$A$1958,">="&DATE(2025,1,1),'עסקאות'!$A$2:$A$1958,"<"&DATE(2026,1,1))} -> 0 | J13: {=_xlfn.SUMIFS('עסקאות'!$M$2:$M$1958,'עסקאות'!$F$2:$F$1958,B13,'עסקאות'!$A$2:$A$1958,">="&DATE(2026,1,1),'עסקאות'!$A$2:$A$1958,"<"&DATE(2027,1,1))} -> 16703
B14: קרוז + ניו יורק 26 | C14: נסיעות וחופשות | D14: 1 | E14: 1 | F14: {=_xlfn.SUMIFS('עסקאות'!$M$2:$M$1958,'עסקאות'!$F$2:$F$1958,B14)} -> 16037 | G14: {=IF(D14=0,"",F14/D14)} -> 16037 | H14: {=F14/20} -> 801.85 | I14: {=_xlfn.SUMIFS('עסקאות'!$M$2:$M$1958,'עסקאות'!$F$2:$F$1958,B14,'עסקאות'!$A$2:$A$1958,">="&DATE(2025,1,1),'עסקאות'!$A$2:$A$1958,"<"&DATE(2026,1,1))} -> 0 | J14: {=_xlfn.SUMIFS('עסקאות'!$M$2:$M$1958,'עסקאות'!$F$2:$F$1958,B14,'עסקאות'!$A$2:$A$1958,">="&DATE(2026,1,1),'עסקאות'!$A$2:$A$1958,"<"&DATE(2027,1,1))} -> 16037
B15: שוויץ 26 | C15: נסיעות וחופשות | D15: 4 | E15: 4 | F15: {=_xlfn.SUMIFS('עסקאות'!$M$2:$M$1958,'עסקאות'!$F$2:$F$1958,B15)} -> 15586 | G15: {=IF(D15=0,"",F15/D15)} -> 3896.5 | H15: {=F15/20} -> 779.3 | I15: {=_xlfn.SUMIFS('עסקאות'!$M$2:$M$1958,'עסקאות'!$F$2:$F$1958,B15,'עסקאות'!$A$2:$A$1958,">="&DATE(2025,1,1),'עסקאות'!$A$2:$A$1958,"<"&DATE(2026,1,1))} -> 100 | J15: {=_xlfn.SUMIFS('עסקאות'!$M$2:$M$1958,'עסקאות'!$F$2:$F$1958,B15,'עסקאות'!$A$2:$A$1958,">="&DATE(2026,1,1),'עסקאות'!$A$2:$A$1958,"<"&DATE(2027,1,1))} -> 15486
B16: אימונים | C16: ספורט | D16: 5 | E16: 5 | F16: {=_xlfn.SUMIFS('עסקאות'!$M$2:$M$1958,'עסקאות'!$F$2:$F$1958,B16)} -> 15441 | G16: {=IF(D16=0,"",F16/D16)} -> 3088.2 | H16: {=F16/20} -> 772.05 | I16: {=_xlfn.SUMIFS('עסקאות'!$M$2:$M$1958,'עסקאות'!$F$2:$F$1958,B16,'עסקאות'!$A$2:$A$1958,">="&DATE(2025,1,1),'עסקאות'!$A$2:$A$1958,"<"&DATE(2026,1,1))} -> 12441 | J16: {=_xlfn.SUMIFS('עסקאות'!$M$2:$M$1958,'עסקאות'!$F$2:$F$1958,B16,'עסקאות'!$A$2:$A$1958,">="&DATE(2026,1,1),'עסקאות'!$A$2:$A$1958,"<"&DATE(2027,1,1))} -> 3000
B17: מלון | C17: נסיעות וחופשות | D17: 7 | E17: 2 | F17: {=_xlfn.SUMIFS('עסקאות'!$M$2:$M$1958,'עסקאות'!$F$2:$F$1958,B17)} -> 11581 | G17: {=IF(D17=0,"",F17/D17)} -> 1654.4286 | H17: {=F17/20} -> 579.05 | I17: {=_xlfn.SUMIFS('עסקאות'!$M$2:$M$1958,'עסקאות'!$F$2:$F$1958,B17,'עסקאות'!$A$2:$A$1958,">="&DATE(2025,1,1),'עסקאות'!$A$2:$A$1958,"<"&DATE(2026,1,1))} -> 11581 | J17: {=_xlfn.SUMIFS('עסקאות'!$M$2:$M$1958,'עסקאות'!$F$2:$F$1958,B17,'עסקאות'!$A$2:$A$1958,">="&DATE(2026,1,1),'עסקאות'!$A$2:$A$1958,"<"&DATE(2027,1,1))} -> 0
B18: טיסה בחגים | C18: נסיעות וחופשות | D18: 1 | E18: 1 | F18: {=_xlfn.SUMIFS('עסקאות'!$M$2:$M$1958,'עסקאות'!$F$2:$F$1958,B18)} -> 11470 | G18: {=IF(D18=0,"",F18/D18)} -> 11470 | H18: {=F18/20} -> 573.5 | I18: {=_xlfn.SUMIFS('עסקאות'!$M$2:$M$1958,'עסקאות'!$F$2:$F$1958,B18,'עסקאות'!$A$2:$A$1958,">="&DATE(2025,1,1),'עסקאות'!$A$2:$A$1958,"<"&DATE(2026,1,1))} -> 11470 | J18: {=_xlfn.SUMIFS('עסקאות'!$M$2:$M$1958,'עסקאות'!$F$2:$F$1958,B18,'עסקאות'!$A$2:$A$1958,">="&DATE(2026,1,1),'עסקאות'!$A$2:$A$1958,"<"&DATE(2027,1,1))} -> 0
... B538: החזר מלון | C538: נסיעות וחופשות | D538: 2 | E538: 1 | F538: {=_xlfn.SUMIFS('עסקאות'!$M$2:$M$1958,'עסקאות'!$F$2:$F$1958,B538)} -> -4190 | G538: {=IF(D538=0,"",F538/D538)} -> -2095 | H538: {=F538/20} -> -209.5 | I538: {=_xlfn.SUMIFS('עסקאות'!$M$2:$M$1958,'עסקאות'!$F$2:$F$1958,B538,'עסקאות'!$A$2:$A$1958,">="&DATE(2025,1,1),'עסקאות'!$A$2:$A$1958,"<"&DATE(2026,1,1))} -> -4190 | J538: {=_xlfn.SUMIFS('עסקאות'!$M$2:$M$1958,'עסקאות'!$F$2:$F$1958,B538,'עסקאות'!$A$2:$A$1958,">="&DATE(2026,1,1),'עסקאות'!$A$2:$A$1958,"<"&DATE(2027,1,1))} -> 0

Sheet עסקאות
A1: חודש | B1: תקופה | C1: גיליון מקור | D1: שורת מקור | E1: תאריך מקור | F1: תיאור | G1: סכום מקור (₪) | H1: קטגוריה מקורית | I1: קבוצה מנורמלת | J1: סיווג בסיס | K1: טיפול בשורה | L1: סטטוס | M1: הוצאה תקנית | N1: הוצאה שוטפת | O1: הכנסה שסווגה מחדש | P1: כרטיס | Q1: הערות | R1: סיכום חופשה
A2: 45658 | B2: 2025-01 | C2: ינואר 25 | D2: 2 | E2: 12 | F2: הכנסה משכר דירה | G2: -6500 | H2: דירה כצנלסון | I2: נכס להשקעה | J2: חריג/נכס | K2: {=IF(OR(H2="ריביות",AND(H2="דירה כצנלסון",G2<0,ISNUMBER(SEARCH("הכנסה",F2)))),"הכנסה שסווגה מחדש",J2)} -> הכנסה שסווגה מחדש | L2: מאושר | M2: {=IF(L2="מאושר",IF(K2="הכנסה שסווגה מחדש",0,G2),0)} -> 0 | N2: {=IF(K2="שוטף",M2,0)} -> 0 | O2: {=IF(K2="הכנסה שסווגה מחדש",-G2,0)} -> 6500 | P2: one zero | R2: לא
A3: 45658 | B3: 2025-01 | C3: ינואר 25 | D3: 3 | E3: 19 | F3: ריבית מחיסון | G3: -143 | H3: ריביות | I3: זרם פיננסי | J3: הכנסה שסווגה מחדש | K3: {=IF(OR(H3="ריביות",AND(H3="דירה כצנלסון",G3<0,ISNUMBER(SEARCH("הכנסה",F3)))),"הכנסה שסווגה מחדש",J3)} -> הכנסה שסווגה מחדש | L3: מאושר | M3: {=IF(L3="מאושר",IF(K3="הכנסה שסווגה מחדש",0,G3),0)} -> 0 | N3: {=IF(K3="שוטף",M3,0)} -> 0 | O3: {=IF(K3="הכנסה שסווגה מחדש",-G3,0)} -> 143 | P3: one zero | R3: לא
A4: 45658 | B4: 2025-01 | C4: ינואר 25 | D4: 4 | F4: חול | G4: 1098 | H4: חול | I4: נסיעות וחופשות | J4: חריג | K4: {=IF(OR(H4="ריביות",AND(H4="דירה כצנלסון",G4<0,ISNUMBER(SEARCH("הכנסה",F4)))),"הכנסה שסווגה מחדש",J4)} -> חריג | L4: מאושר | M4: {=IF(L4="מאושר",IF(K4="הכנסה שסווגה מחדש",0,G4),0)} -> 1098 | N4: {=IF(K4="שוטף",M4,0)} -> 0 | O4: {=IF(K4="הכנסה שסווגה מחדש",-G4,0)} -> 0 | P4: one zero זיו | R4: לא
A5: 45658 | B5: 2025-01 | C5: ינואר 25 | D5: 5 | E5: 7 | F5: חשמל כצלנסון | G5: 60 | H5: דירה כצנלסון | I5: נכס להשקעה | J5: חריג/נכס | K5: {=IF(OR(H5="ריביות",AND(H5="דירה כצנלסון",G5<0,ISNUMBER(SEARCH("הכנסה",F5)))),"הכנסה שסווגה מחדש",J5)} -> חריג/נכס | L5: מאושר | M5: {=IF(L5="מאושר",IF(K5="הכנסה שסווגה מחדש",0,G5),0)} -> 60 | N5: {=IF(K5="שוטף",M5,0)} -> 0 | O5: {=IF(K5="הכנסה שסווגה מחדש",-G5,0)} -> 0 | P5: one zero זיו | R5: לא
A6: 45658 | B6: 2025-01 | C6: ינואר 25 | D6: 6 | E6: 10 | F6: יונקלו | G6: 954 | H6: אופנה | I6: אופנה | J6: שוטף | K6: {=IF(OR(H6="ריביות",AND(H6="דירה כצנלסון",G6<0,ISNUMBER(SEARCH("הכנסה",F6)))),"הכנסה שסווגה מחדש",J6)} -> שוטף | L6: מאושר | M6: {=IF(L6="מאושר",IF(K6="הכנסה שסווגה מחדש",0,G6),0)} -> 954 | N6: {=IF(K6="שוטף",M6,0)} -> 954 | O6: {=IF(K6="הכנסה שסווגה מחדש",-G6,0)} -> 0 | P6: one zero זיו | R6: לא
A7: 45658 | B7: 2025-01 | C7: ינואר 25 | D7: 7 | E7: 11 | F7: קניות איפור | G7: 76 | H7: קוסמטיקה | I7: קוסמטיקה | J7: שוטף | K7: {=IF(OR(H7="ריביות",AND(H7="דירה כצנלסון",G7<0,ISNUMBER(SEARCH("הכנסה",F7)))),"הכנסה שסווגה מחדש",J7)} -> שוטף | L7: מאושר | M7: {=IF(L7="מאושר",IF(K7="הכנסה שסווגה מחדש",0,G7),0)} -> 76 | N7: {=IF(K7="שוטף",M7,0)} -> 76 | O7: {=IF(K7="הכנסה שסווגה מחדש",-G7,0)} -> 0 | P7: one zero זיו | R7: לא
A8: 45658 | B8: 2025-01 | C8: ינואר 25 | D8: 8 | E8: 16 | F8: פיצוציה | G8: 14 | H8: אוכל בחוץ | I8: אוכל בחוץ | J8: שוטף | K8: {=IF(OR(H8="ריביות",AND(H8="דירה כצנלסון",G8<0,ISNUMBER(SEARCH("הכנסה",F8)))),"הכנסה שסווגה מחדש",J8)} -> שוטף | L8: מאושר | M8: {=IF(L8="מאושר",IF(K8="הכנסה שסווגה מחדש",0,G8),0)} -> 14 | N8: {=IF(K8="שוטף",M8,0)} -> 14 | O8: {=IF(K8="הכנסה שסווגה מחדש",-G8,0)} -> 0 | P8: one zero זיו | R8: לא
A9: 45658 | B9: 2025-01 | C9: ינואר 25 | D9: 9 | E9: 24 | F9: יקב נווה ירק | G9: 365 | H9: אוכל בחוץ | I9: אוכל בחוץ | J9: שוטף | K9: {=IF(OR(H9="ריביות",AND(H9="דירה כצנלסון",G9<0,ISNUMBER(SEARCH("הכנסה",F9)))),"הכנסה שסווגה מחדש",J9)} -> שוטף | L9: מאושר | M9: {=IF(L9="מאושר",IF(K9="הכנסה שסווגה מחדש",0,G9),0)} -> 365 | N9: {=IF(K9="שוטף",M9,0)} -> 365 | O9: {=IF(K9="הכנסה שסווגה מחדש",-G9,0)} -> 0 | P9: one zero זיו | R9: לא
A10: 45658 | B10: 2025-01 | C10: ינואר 25 | D10: 10 | E10: 29 | F10: פורטר | G10: 205 | H10: אוכל בחוץ | I10: אוכל בחוץ | J10: שוטף | K10: {=IF(OR(H10="ריביות",AND(H10="דירה כצנלסון",G10<0,ISNUMBER(SEARCH("הכנסה",F10)))),"הכנסה שסווגה מחדש",J10)} -> שוטף | L10: מאושר | M10: {=IF(L10="מאושר",IF(K10="הכנסה שסווגה מחדש",0,G10),0)} -> 205 | N10: {=IF(K10="שוטף",M10,0)} -> 205 | O10: {=IF(K10="הכנסה שסווגה מחדש",-G10,0)} -> 0 | P10: one zero זיו | R10: לא
A11: 45658 | B11: 2025-01 | C11: ינואר 25 | D11: 11 | E11: 7 | F11: מים | G11: 125 | H11: מגורים צריכה | I11: דיור – בית מגורים | J11: שוטף | K11: {=IF(OR(H11="ריביות",AND(H11="דירה כצנלסון",G11<0,ISNUMBER(SEARCH("הכנסה",F11)))),"הכנסה שסווגה מחדש",J11)} -> שוטף | L11: מאושר | M11: {=IF(L11="מאושר",IF(K11="הכנסה שסווגה מחדש",0,G11),0)} -> 125 | N11: {=IF(K11="שוטף",M11,0)} -> 125 | O11: {=IF(K11="הכנסה שסווגה מחדש",-G11,0)} -> 0 | P11: one zero עינור | R11: לא
A12: 45658 | B12: 2025-01 | C12: ינואר 25 | D12: 12 | E12: 7 | F12: מים כצנלסון | G12: 8 | H12: דירה כצנלסון | I12: נכס להשקעה | J12: חריג/נכס | K12: {=IF(OR(H12="ריביות",AND(H12="דירה כצנלסון",G12<0,ISNUMBER(SEARCH("הכנסה",F12)))),"הכנסה שסווגה מחדש",J12)} -> חריג/נכס | L12: מאושר | M12: {=IF(L12="מאושר",IF(K12="הכנסה שסווגה מחדש",0,G12),0)} -> 8 | N12: {=IF(K12="שוטף",M12,0)} -> 0 | O12: {=IF(K12="הכנסה שסווגה מחדש",-G12,0)} -> 0 | P12: one zero עינור | R12: לא
A13: 45658 | B13: 2025-01 | C13: ינואר 25 | D13: 13 | E13: 12 | F13: לק | G13: 110 | H13: קוסמטיקה | I13: קוסמטיקה | J13: שוטף | K13: {=IF(OR(H13="ריביות",AND(H13="דירה כצנלסון",G13<0,ISNUMBER(SEARCH("הכנסה",F13)))),"הכנסה שסווגה מחדש",J13)} -> שוטף | L13: מאושר | M13: {=IF(L13="מאושר",IF(K13="הכנסה שסווגה מחדש",0,G13),0)} -> 110 | N13: {=IF(K13="שוטף",M13,0)} -> 110 | O13: {=IF(K13="הכנסה שסווגה מחדש",-G13,0)} -> 0 | P13: one zero עינור | R13: לא
A14: 45658 | B14: 2025-01 | C14: ינואר 25 | D14: 14 | E14: 12 | F14: סופר | G14: 14 | H14: מזון לבית | I14: מזון לבית | J14: שוטף | K14: {=IF(OR(H14="ריביות",AND(H14="דירה כצנלסון",G14<0,ISNUMBER(SEARCH("הכנסה",F14)))),"הכנסה שסווגה מחדש",J14)} -> שוטף | L14: מאושר | M14: {=IF(L14="מאושר",IF(K14="הכנסה שסווגה מחדש",0,G14),0)} -> 14 | N14: {=IF(K14="שוטף",M14,0)} -> 14 | O14: {=IF(K14="הכנסה שסווגה מחדש",-G14,0)} -> 0 | P14: one zero עינור | R14: לא
A15: 45658 | B15: 2025-01 | C15: ינואר 25 | D15: 15 | F15: משחק | G15: 50 | H15: פנאי | I15: פנאי | J15: שוטף | K15: {=IF(OR(H15="ריביות",AND(H15="דירה כצנלסון",G15<0,ISNUMBER(SEARCH("הכנסה",F15)))),"הכנסה שסווגה מחדש",J15)} -> שוטף | L15: מאושר | M15: {=IF(L15="מאושר",IF(K15="הכנסה שסווגה מחדש",0,G15),0)} -> 50 | N15: {=IF(K15="שוטף",M15,0)} -> 50 | O15: {=IF(K15="הכנסה שסווגה מחדש",-G15,0)} -> 0 | P15: one zero עינור | R15: לא
A16: 45658 | B16: 2025-01 | C16: ינואר 25 | D16: 16 | F16: חול | G16: 1065 | H16: חול | I16: נסיעות וחופשות | J16: חריג | K16: {=IF(OR(H16="ריביות",AND(H16="דירה כצנלסון",G16<0,ISNUMBER(SEARCH("הכנסה",F16)))),"הכנסה שסווגה מחדש",J16)} -> חריג | L16: מאושר | M16: {=IF(L16="מאושר",IF(K16="הכנסה שסווגה מחדש",0,G16),0)} -> 1065 | N16: {=IF(K16="שוטף",M16,0)} -> 0 | O16: {=IF(K16="הכנסה שסווגה מחדש",-G16,0)} -> 0 | P16: one zero עינור | R16: לא
A17: 45658 | B17: 2025-01 | C17: ינואר 25 | D17: 17 | E17: 26 | F17: שיין | G17: 286 | H17: אופנה | I17: אופנה | J17: שוטף | K17: {=IF(OR(H17="ריביות",AND(H17="דירה כצנלסון",G17<0,ISNUMBER(SEARCH("הכנסה",F17)))),"הכנסה שסווגה מחדש",J17)} -> שוטף | L17: מאושר | M17: {=IF(L17="מאושר",IF(K17="הכנסה שסווגה מחדש",0,G17),0)} -> 286 | N17: {=IF(K17="שוטף",M17,0)} -> 286 | O17: {=IF(K17="הכנסה שסווגה מחדש",-G17,0)} -> 0 | P17: one zero עינור | R17: לא
A18: 45658 | B18: 2025-01 | C18: ינואר 25 | D18: 18 | F18: אימונים | G18: 522 | H18: ספורט | I18: ספורט | J18: שוטף | K18: {=IF(OR(H18="ריביות",AND(H18="דירה כצנלסון",G18<0,ISNUMBER(SEARCH("הכנסה",F18)))),"הכנסה שסווגה מחדש",J18)} -> שוטף | L18: מאושר | M18: {=IF(L18="מאושר",IF(K18="הכנסה שסווגה מחדש",0,G18),0)} -> 522 | N18: {=IF(K18="שוטף",M18,0)} -> 522 | O18: {=IF(K18="הכנסה שסווגה מחדש",-G18,0)} -> 0 | P18: אחר - עינור | R18: לא
A19: 45658 | B19: 2025-01 | C19: ינואר 25 | D19: 19 | E19: 18 | F19: ארנונה | G19: 950 | H19: מגורים צריכה | I19: דיור – בית מגורים | J19: שוטף | K19: {=IF(OR(H19="ריביות",AND(H19="דירה כצנלסון",G19<0,ISNUMBER(SEARCH("הכנסה",F19)))),"הכנסה שסווגה מחדש",J19)} -> שוטף | L19: מאושר | M19: {=IF(L19="מאושר",IF(K19="הכנסה שסווגה מחדש",0,G19),0)} -> 950 | N19: {=IF(K19="שוטף",M19,0)} -> 950 | O19: {=IF(K19="הכנסה שסווגה מחדש",-G19,0)} -> 0 | P19: אמקס זיו | R19: לא
A20: 45658 | B20: 2025-01 | C20: ינואר 25 | D20: 20 | E20: 18 | F20: גז | G20: 39 | H20: מגורים צריכה | I20: דיור – בית מגורים | J20: שוטף | K20: {=IF(OR(H20="ריביות",AND(H20="דירה כצנלסון",G20<0,ISNUMBER(SEARCH("הכנסה",F20)))),"הכנסה שסווגה מחדש",J20)} -> שוטף | L20: מאושר | M20: {=IF(L20="מאושר",IF(K20="הכנסה שסווגה מחדש",0,G20),0)} -> 39 | N20: {=IF(K20="שוטף",M20,0)} -> 39 | O20: {=IF(K20="הכנסה שסווגה מחדש",-G20,0)} -> 0 | P20: אמקס זיו | R20: לא
A21: 45658 | B21: 2025-01 | C21: ינואר 25 | D21: 21 | E21: 12 | F21: סלולר + אינטרנט | G21: 169 | H21: מגורים חודשי | I21: דיור – בית מגורים | J21: שוטף | K21: {=IF(OR(H21="ריביות",AND(H21="דירה כצנלסון",G21<0,ISNUMBER(SEARCH("הכנסה",F21)))),"הכנסה שסווגה מחדש",J21)} -> שוטף | L21: מאושר | M21: {=IF(L21="מאושר",IF(K21="הכנסה שסווגה מחדש",0,G21),0)} -> 169 | N21: {=IF(K21="שוטף",M21,0)} -> 169 | O21: {=IF(K21="הכנסה שסווגה מחדש",-G21,0)} -> 0 | P21: אמקס זיו | R21: לא
A22: 45658 | B22: 2025-01 | C22: ינואר 25 | D22: 22 | E22: 28 | F22: ביטוח מבנה | G22: 87 | H22: דירה כצנלסון | I22: נכס להשקעה | J22: חריג/נכס | K22: {=IF(OR(H22="ריביות",AND(H22="דירה כצנלסון",G22<0,ISNUMBER(SEARCH("הכנסה",F22)))),"הכנסה שסווגה מחדש",J22)} -> חריג/נכס | L22: מאושר | M22: {=IF(L22="מאושר",IF(K22="הכנסה שסווגה מחדש",0,G22),0)} -> 87 | N22: {=IF(K22="שוטף",M22,0)} -> 0 | O22: {=IF(K22="הכנסה שסווגה מחדש",-G22,0)} -> 0 | P22: אמקס זיו | R22: לא
A23: 45658 | B23: 2025-01 | C23: ינואר 25 | D23: 23 | E23: 28 | F23: ביטוח חיים | G23: 29 | H23: דירה כצנלסון | I23: נכס להשקעה | J23: חריג/נכס | K23: {=IF(OR(H23="ריביות",AND(H23="דירה כצנלסון",G23<0,ISNUMBER(SEARCH("הכנסה",F23)))),"הכנסה שסווגה מחדש",J23)} -> חריג/נכס | L23: מאושר | M23: {=IF(L23="מאושר",IF(K23="הכנסה שסווגה מחדש",0,G23),0)} -> 29 | N23: {=IF(K23="שוטף",M23,0)} -> 0 | O23: {=IF(K23="הכנסה שסווגה מחדש",-G23,0)} -> 0 | P23: אמקס זיו | R23: לא
A24: 45658 | B24: 2025-01 | C24: ינואר 25 | D24: 24 | E24: 25 | F24: חניון הדסה | G24: 54 | H24: תחבורה | I24: תחבורה | J24: שוטף | K24: {=IF(OR(H24="ריביות",AND(H24="דירה כצנלסון",G24<0,ISNUMBER(SEARCH("הכנסה",F24)))),"הכנסה שסווגה מחדש",J24)} -> שוטף | L24: מאושר | M24: {=IF(L24="מאושר",IF(K24="הכנסה שסווגה מחדש",0,G24),0)} -> 54 | N24: {=IF(K24="שוטף",M24,0)} -> 54 | O24: {=IF(K24="הכנסה שסווגה מחדש",-G24,0)} -> 0 | P24: אמקס זיו | R24: לא
A25: 45658 | B25: 2025-01 | C25: ינואר 25 | D25: 25 | E25: 25 | F25: תחבץ | G25: 36 | H25: תחבורה | I25: תחבורה | J25: שוטף | K25: {=IF(OR(H25="ריביות",AND(H25="דירה כצנלסון",G25<0,ISNUMBER(SEARCH("הכנסה",F25)))),"הכנסה שסווגה מחדש",J25)} -> שוטף | L25: מאושר | M25: {=IF(L25="מאושר",IF(K25="הכנסה שסווגה מחדש",0,G25),0)} -> 36 | N25: {=IF(K25="שוטף",M25,0)} -> 36 | O25: {=IF(K25="הכנסה שסווגה מחדש",-G25,0)} -> 0 | P25: אמקס זיו | R25: לא
A26: 45658 | B26: 2025-01 | C26: ינואר 25 | D26: 26 | E26: 25 | F26: דלק | G26: 208 | H26: תחבורה | I26: תחבורה | J26: שוטף | K26: {=IF(OR(H26="ריביות",AND(H26="דירה כצנלסון",G26<0,ISNUMBER(SEARCH("הכנסה",F26)))),"הכנסה שסווגה מחדש",J26)} -> שוטף | L26: מאושר | M26: {=IF(L26="מאושר",IF(K26="הכנסה שסווגה מחדש",0,G26),0)} -> 208 | N26: {=IF(K26="שוטף",M26,0)} -> 208 | O26: {=IF(K26="הכנסה שסווגה מחדש",-G26,0)} -> 0 | P26: אמקס זיו | R26: לא
A27: 45658 | B27: 2025-01 | C27: ינואר 25 | D27: 27 | E27: 23 | F27: סופר פארם | G27: 34 | H27: בריאות | I27: בריאות וטיפולים | J27: שוטף | K27: {=IF(OR(H27="ריביות",AND(H27="דירה כצנלסון",G27<0,ISNUMBER(SEARCH("הכנסה",F27)))),"הכנסה שסווגה מחדש",J27)} -> שוטף | L27: מאושר | M27: {=IF(L27="מאושר",IF(K27="הכנסה שסווגה מחדש",0,G27),0)} -> 34 | N27: {=IF(K27="שוטף",M27,0)} -> 34 | O27: {=IF(K27="הכנסה שסווגה מחדש",-G27,0)} -> 0 | P27: אמקס זיו | R27: לא
A28: 45658 | B28: 2025-01 | C28: ינואר 25 | D28: 28 | E28: 21 | F28: סופר פארם | G28: 20 | H28: בריאות | I28: בריאות וטיפולים | J28: שוטף | K28: {=IF(OR(H28="ריביות",AND(H28="דירה כצנלסון",G28<0,ISNUMBER(SEARCH("הכנסה",F28)))),"הכנסה שסווגה מחדש",J28)} -> שוטף | L28: מאושר | M28: {=IF(L28="מאושר",IF(K28="הכנסה שסווגה מחדש",0,G28),0)} -> 20 | N28: {=IF(K28="שוטף",M28,0)} -> 20 | O28: {=IF(K28="הכנסה שסווגה מחדש",-G28,0)} -> 0 | P28: אמקס זיו | R28: לא
A29: 45658 | B29: 2025-01 | C29: ינואר 25 | D29: 29 | E29: 21 | F29: שיניים | G29: 110 | H29: בריאות | I29: בריאות וטיפולים | J29: שוטף | K29: {=IF(OR(H29="ריביות",AND(H29="דירה כצנלסון",G29<0,ISNUMBER(SEARCH("הכנסה",F29)))),"הכנסה שסווגה מחדש",J29)} -> שוטף | L29: מאושר | M29: {=IF(L29="מאושר",IF(K29="הכנסה שסווגה מחדש",0,G29),0)} -> 110 | N29: {=IF(K29="שוטף",M29,0)} -> 110 | O29: {=IF(K29="הכנסה שסווגה מחדש",-G29,0)} -> 0 | P29: אמקס זיו | R29: לא
A30: 45658 | B30: 2025-01 | C30: ינואר 25 | D30: 30 | E30: 19 | F30: טסט לרכב | G30: 123 | H30: תחבורה | I30: תחבורה | J30: שוטף | K30: {=IF(OR(H30="ריביות",AND(H30="דירה כצנלסון",G30<0,ISNUMBER(SEARCH("הכנסה",F30)))),"הכנסה שסווגה מחדש",J30)} -> שוטף | L30: מאושר | M30: {=IF(L30="מאושר",IF(K30="הכנסה שסווגה מחדש",0,G30),0)} -> 123 | N30: {=IF(K30="שוטף",M30,0)} -> 123 | O30: {=IF(K30="הכנסה שסווגה מחדש",-G30,0)} -> 0 | P30: אמקס זיו | R30: לא
... A53: 45658 | B53: 2025-01 | C53: ינואר 25 | D53: 53 | E53: 24 | F53: סופר | G53: 327 | H53: מזון לבית | I53: מזון לבית | J53: שוטף | K53: {=IF(OR(H53="ריביות",AND(H53="דירה כצנלסון",G53<0,ISNUMBER(SEARCH("הכנסה",F53)))),"הכנסה שסווגה מחדש",J53)} -> שוטף | L53: מאושר | M53: {=IF(L53="מאושר",IF(K53="הכנסה שסווגה מחדש",0,G53),0)} -> 327 | N53: {=IF(K53="שוטף",M53,0)} -> 327 | O53: {=IF(K53="הכנסה שסווגה מחדש",-G53,0)} -> 0 | P53: הוט זיו | R53: לא
A54: 45658 | B54: 2025-01 | C54: ינואר 25 | D54: 54 | F54: מנקה | G54: 400 | H54: מגורים צריכה | I54: דיור – בית מגורים | J54: שוטף | K54: {=IF(OR(H54="ריביות",AND(H54="דירה כצנלסון",G54<0,ISNUMBER(SEARCH("הכנסה",F54)))),"הכנסה שסווגה מחדש",J54)} -> שוטף | L54: מאושר | M54: {=IF(L54="מאושר",IF(K54="הכנסה שסווגה מחדש",0,G54),0)} -> 400 | N54: {=IF(K54="שוטף",M54,0)} -> 400 | O54: {=IF(K54="הכנסה שסווגה מחדש",-G54,0)} -> 0 | P54: מזומן | R54: לא
A55: 45658 | B55: 2025-01 | C55: ינואר 25 | D55: 55 | E55: 28 | F55: קרפור | G55: 13 | H55: מזון לבית | I55: מזון לבית | J55: שוטף | K55: {=IF(OR(H55="ריביות",AND(H55="דירה כצנלסון",G55<0,ISNUMBER(SEARCH("הכנסה",F55)))),"הכנסה שסווגה מחדש",J55)} -> שוטף | L55: מאושר | M55: {=IF(L55="מאושר",IF(K55="הכנסה שסווגה מחדש",0,G55),0)} -> 13 | N55: {=IF(K55="שוטף",M55,0)} -> 13 | O55: {=IF(K55="הכנסה שסווגה מחדש",-G55,0)} -> 0 | P55: מקס זיו | R55: לא
A56: 45658 | B56: 2025-01 | C56: ינואר 25 | D56: 56 | E56: 15 | F56: טיפול רכב | G56: 1221 | H56: תחבורה | I56: תחבורה | J56: שוטף | K56: {=IF(OR(H56="ריביות",AND(H56="דירה כצנלסון",G56<0,ISNUMBER(SEARCH("הכנסה",F56)))),"הכנסה שסווגה מחדש",J56)} -> שוטף | L56: מאושר | M56: {=IF(L56="מאושר",IF(K56="הכנסה שסווגה מחדש",0,G56),0)} -> 1221 | N56: {=IF(K56="שוטף",M56,0)} -> 1221 | O56: {=IF(K56="הכנסה שסווגה מחדש",-G56,0)} -> 0 | P56: מקס עינור | R56: לא
A57: 45658 | B57: 2025-01 | C57: ינואר 25 | D57: 57 | E57: 19 | F57: מאפיה | G57: 59 | H57: אוכל בחוץ | I57: אוכל בחוץ | J57: שוטף | K57: {=IF(OR(H57="ריביות",AND(H57="דירה כצנלסון",G57<0,ISNUMBER(SEARCH("הכנסה",F57)))),"הכנסה שסווגה מחדש",J57)} -> שוטף | L57: מאושר | M57: {=IF(L57="מאושר",IF(K57="הכנסה שסווגה מחדש",0,G57),0)} -> 59 | N57: {=IF(K57="שוטף",M57,0)} -> 59 | O57: {=IF(K57="הכנסה שסווגה מחדש",-G57,0)} -> 0 | P57: מקס עינור | R57: לא
A58: 45658 | B58: 2025-01 | C58: ינואר 25 | D58: 58 | E58: 25 | F58: חומוס | G58: 33 | H58: אוכל בחוץ | I58: אוכל בחוץ | J58: שוטף | K58: {=IF(OR(H58="ריביות",AND(H58="דירה כצנלסון",G58<0,ISNUMBER(SEARCH("הכנסה",F58)))),"הכנסה שסווגה מחדש",J58)} -> שוטף | L58: מאושר | M58: {=IF(L58="מאושר",IF(K58="הכנסה שסווגה מחדש",0,G58),0)} -> 33 | N58: {=IF(K58="שוטף",M58,0)} -> 33 | O58: {=IF(K58="הכנסה שסווגה מחדש",-G58,0)} -> 0 | P58: מקס עינור | R58: לא
A59: 45658 | B59: 2025-01 | C59: ינואר 25 | D59: 59 | E59: 26 | F59: ביט (אוכל) | G59: 25 | H59: אוכל בחוץ | I59: אוכל בחוץ | J59: שוטף | K59: {=IF(OR(H59="ריביות",AND(H59="דירה כצנלסון",G59<0,ISNUMBER(SEARCH("הכנסה",F59)))),"הכנסה שסווגה מחדש",J59)} -> שוטף | L59: מאושר | M59: {=IF(L59="מאושר",IF(K59="הכנסה שסווגה מחדש",0,G59),0)} -> 25 | N59: {=IF(K59="שוטף",M59,0)} -> 25 | O59: {=IF(K59="הכנסה שסווגה מחדש",-G59,0)} -> 0 | P59: מקס עינור | R59: לא
A60: 45658 | B60: 2025-01 | C60: ינואר 25 | D60: 60 | E60: 26 | F60: שמלת כלה (ביט) | G60: 2500 | H60: חתונה | I60: חתונה | J60: חריג | K60: {=IF(OR(H60="ריביות",AND(H60="דירה כצנלסון",G60<0,ISNUMBER(SEARCH("הכנסה",F60)))),"הכנסה שסווגה מחדש",J60)} -> חריג | L60: מאושר | M60: {=IF(L60="מאושר",IF(K60="הכנסה שסווגה מחדש",0,G60),0)} -> 2500 | N60: {=IF(K60="שוטף",M60,0)} -> 0 | O60: {=IF(K60="הכנסה שסווגה מחדש",-G60,0)} -> 0 | P60: מקס עינור | R60: לא
A61: 45658 | B61: 2025-01 | C61: ינואר 25 | D61: 61 | E61: 27 | F61: ביטוח חובה | G61: 1797 | H61: תחבורה | I61: תחבורה | J61: שוטף | K61: {=IF(OR(H61="ריביות",AND(H61="דירה כצנלסון",G61<0,ISNUMBER(SEARCH("הכנסה",F61)))),"הכנסה שסווגה מחדש",J61)} -> שוטף | L61: מאושר | M61: {=IF(L61="מאושר",IF(K61="הכנסה שסווגה מחדש",0,G61),0)} -> 1797 | N61: {=IF(K61="שוטף",M61,0)} -> 1797 | O61: {=IF(K61="הכנסה שסווגה מחדש",-G61,0)} -> 0 | P61: מקס עינור | R61: לא
A62: 45658 | B62: 2025-01 | C62: ינואר 25 | D62: 62 | E62: 28 | F62: ביטוח מקיף | G62: 2683 | H62: תחבורה | I62: תחבורה | J62: שוטף | K62: {=IF(OR(H62="ריביות",AND(H62="דירה כצנלסון",G62<0,ISNUMBER(SEARCH("הכנסה",F62)))),"הכנסה שסווגה מחדש",J62)} -> שוטף | L62: מאושר | M62: {=IF(L62="מאושר",IF(K62="הכנסה שסווגה מחדש",0,G62),0)} -> 2683 | N62: {=IF(K62="שוטף",M62,0)} -> 2683 | O62: {=IF(K62="הכנסה שסווגה מחדש",-G62,0)} -> 0 | P62: מקס עינור | R62: לא
...

Sheet הכנסות
A1: חודש | B1: תקופה | C1: מקור הכנסה | D1: סכום (₪) | E1: סוג הכנסה | F1: גיליון מקור
A2: 45658 | B2: 2025-01 | C2: משכורת זיו | D2: 46854 | E2: {=IF(OR(ISNUMBER(SEARCH("ESPP",C2)),ISNUMBER(SEARCH("RSU",C2))),"הוני","שוטף")} -> שוטף | F2: ינואר 25
A3: 45658 | B3: 2025-01 | C3: משכורת עינור | D3: 21647 | E3: {=IF(OR(ISNUMBER(SEARCH("ESPP",C3)),ISNUMBER(SEARCH("RSU",C3))),"הוני","שוטף")} -> שוטף | F3: ינואר 25
A4: 45658 | B4: 2025-01 | C4: ESPP | D4: 77907 | E4: {=IF(OR(ISNUMBER(SEARCH("ESPP",C4)),ISNUMBER(SEARCH("RSU",C4))),"הוני","שוטף")} -> הוני | F4: ינואר 25
A5: 45689 | B5: 2025-02 | C5: משכורת זיו | D5: 18338 | E5: {=IF(OR(ISNUMBER(SEARCH("ESPP",C5)),ISNUMBER(SEARCH("RSU",C5))),"הוני","שוטף")} -> שוטף | F5: פברואר 25
A6: 45689 | B6: 2025-02 | C6: משכורת עינור | D6: 21641 | E6: {=IF(OR(ISNUMBER(SEARCH("ESPP",C6)),ISNUMBER(SEARCH("RSU",C6))),"הוני","שוטף")} -> שוטף | F6: פברואר 25
A7: 45689 | B7: 2025-02 | C7: ESPP | D7: 0 | E7: {=IF(OR(ISNUMBER(SEARCH("ESPP",C7)),ISNUMBER(SEARCH("RSU",C7))),"הוני","שוטף")} -> הוני | F7: פברואר 25
A8: 45717 | B8: 2025-03 | C8: משכורת זיו | D8: 16076 | E8: {=IF(OR(ISNUMBER(SEARCH("ESPP",C8)),ISNUMBER(SEARCH("RSU",C8))),"הוני","שוטף")} -> שוטף | F8: מרץ 25
A9: 45717 | B9: 2025-03 | C9: משכורת עינור | D9: 21644 | E9: {=IF(OR(ISNUMBER(SEARCH("ESPP",C9)),ISNUMBER(SEARCH("RSU",C9))),"הוני","שוטף")} -> שוטף | F9: מרץ 25
A10: 45717 | B10: 2025-03 | C10: ESPP | D10: 32403 | E10: {=IF(OR(ISNUMBER(SEARCH("ESPP",C10)),ISNUMBER(SEARCH("RSU",C10))),"הוני","שוטף")} -> הוני | F10: מרץ 25
A11: 45748 | B11: 2025-04 | C11: משכורת זיו | D11: 15210 | E11: {=IF(OR(ISNUMBER(SEARCH("ESPP",C11)),ISNUMBER(SEARCH("RSU",C11))),"הוני","שוטף")} -> שוטף | F11: אפריל 25
A12: 45748 | B12: 2025-04 | C12: משכורת עינור | D12: 18843 | E12: {=IF(OR(ISNUMBER(SEARCH("ESPP",C12)),ISNUMBER(SEARCH("RSU",C12))),"הוני","שוטף")} -> שוטף | F12: אפריל 25
A13: 45748 | B13: 2025-04 | C13: ESPP | D13: 0 | E13: {=IF(OR(ISNUMBER(SEARCH("ESPP",C13)),ISNUMBER(SEARCH("RSU",C13))),"הוני","שוטף")} -> הוני | F13: אפריל 25
... A98: 46235 | B98: 2026-08 | C98: RSU | D98: 0 | E98: {=IF(OR(ISNUMBER(SEARCH("ESPP",C98)),ISNUMBER(SEARCH("RSU",C98))),"הוני","שוטף")} -> הוני | F98: אוגוסט 26

Sheet פירוט חופשות
B2: פירוט חופשות
B3: פירוט משלים בלבד; אין לחבר לסיכום החודשי משום שחלק מהסכומים כבר מופיעים בעסקאות
B6: חופשה | C6: שורת מקור | D6: תאריך | E6: תיאור | F6: סכום (₪) | G6: קטגוריה | H6: כרטיס | I6: סטטוס
B7: יפן 25 | C7: 2 | D7: 2.2 | E7: טיסה | F7: 11469 | G7: טיסה | H7: 10 עינור | I7: מאושר
B8: יפן 25 | C8: 3 | D8: 10.3 | E8: טיסה לאוסקה | F8: 2994 | G8: טיסה | H8: 10 עינור | I8: מאושר
B9: יפן 25 | C9: 4 | D9: 14.3 | E9: מלון טויומה | F9: 320 | G9: לינה | H9: 10 זיו | I9: מאושר
B10: יפן 25 | C10: 5 | D10: 14.3 | E10: מלון נגנו | F10: 33 | G10: לינה | H10: 10 זיו | I10: מאושר
B11: יפן 25 | C11: 6 | D11: 14.3 | E11: מלון אונסונים | F11: 3549 | G11: לינה | H11: 10 זיו | I11: מאושר
B12: יפן 25 | C12: 7 | D12: 27.6 | E12: מלון הירושימה | F12: 922 | G12: לינה | H12: 10 זיו | I12: מאושר
B13: יפן 25 | C13: 8 | D13: 19.7 | E13: מלון אוסקה | F13: 1127 | G13: לינה | H13: אמקס עינור | I13: מאושר
